<?xml version="1.0" encoding="utf-8"?>
<!-- Last edited on 2024-10-17 (v12).
This URDF was automatically created by SolidWorks to URDF Exporter! Originally created by Stephen Brawner (brawner@gmail.com) 
     Commit Version: 1.6.0-4-g7f85cfe  Build Version: 1.6.7995.38578
     For more information, please see http://wiki.ros.org/sw_urdf_exporter -->
<robot
  name="MG6010">
  <link
    name="base_link">
    <inertial>
      <origin
        xyz="-0.001334 3.1586E-15 0.18943"
        rpy="0 0 0" />
      <mass
        value="29.128" />
      <inertia
        ixx="2.1068"
        ixy="-3.3076E-15"
        ixz="-0.0069722"
        iyy="2.1115"
        iyz="1.688E-14"
        izz="0.22457" />
    </inertial>
    <visual>
      <origin
        xyz="0 0 0"
        rpy="0 0 0" />
      <geometry>
        <mesh
          filename="package://robot_description/meshes/base_link.STL" />
      </geometry>
      <material
        name="">
        <color
          rgba="0.65098 0.61961 0.58824 1" />
      </material>
    </visual>
    <collision>
      <origin
        xyz="0 0 0"
        rpy="0 0 0" />
      <geometry>
        <mesh
          filename="package://robot_description/meshes/base_link.STL" />
      </geometry>
    </collision>
  </link>
  <link
    name="link2">
    <inertial>
      <origin
        xyz="0.0023258 0.39197 0.0012124"
        rpy="0 0 0" />
      <mass
        value="7.2824" />
      <inertia
        ixx="0.56505"
        ixy="-0.0011051"
        ixz="0.00023875"
        iyy="0.0071252"
        iyz="-0.00046822"
        izz="0.56327" />
    </inertial>
    <visual>
      <origin
        xyz="0 0 -0.445"
        rpy="0 0 0" />
      <geometry>
        <mesh
          filename="package://robot_description/meshes/link2.STL" />
      </geometry>
      <material
        name="">
        <color
          rgba="1 1 0 1" />
      </material>
    </visual>
    <collision>
      <origin
        xyz="0 0 0"
        rpy="0 0 0" />
      <geometry>
        <mesh
          filename="package://robot_description/meshes/link2.STL" />
      </geometry>
    </collision>
  </link>
  <joint
    name="joint 2"
    type="prismatic">
    <origin
      xyz="0 0 0.45922"
      rpy="0 0 0" />
    <parent
      link="base_link" />
    <child
      link="link2" />
    <axis
      xyz="0 0 1" />
    <limit
      lower="0.1"
      upper="0.32"
      effort="0"
      velocity="0" />
  </joint>
  <link
    name="link4">
    <inertial>
      <origin
        xyz="-0.044144 0.0378 -0.072925"
        rpy="0 0 0" />
      <mass
        value="0.86357" />
      <inertia
        ixx="0.0063398"
        ixy="0.00091722"
        ixz="-0.0017328"
        iyy="0.0061419"
        iyz="0.0015638"
        izz="0.0031822" />
    </inertial>
    <visual>
      <origin
        xyz="0.008 -0.334 -0.459"
        rpy="0 0 0" />
      <geometry>
        <mesh
          filename="package://robot_description/meshes/link4.STL" />
      </geometry>
      <material
        name="">
        <color
          rgba="0.292156862745098 0.119607843137255 0.933333333333333 1" />
      </material>
    </visual>
    <collision>
      <origin
        xyz="0 0 0"
        rpy="0 0 0" />
      <geometry>
        <mesh
          filename="package://robot_description/meshes/link4.STL" />
      </geometry>
    </collision>
  </link>
  <joint
    name="joint 4"
    type="prismatic">
    <origin
      xyz="0 0.33411 0"
      rpy="0 0 0" />
    <parent
      link="link2" />
    <child
      link="link4" />
    <axis
      xyz="0 1 0" />
    <limit
      lower="-0.250"
      upper="0.350"
      effort="0"
      velocity="0" />
  </joint>
  <link
    name="link7">
    <inertial>
      <origin
        xyz="-0.004 0.0041238 2.7756E-17"
        rpy="0 0 0" />
      <mass
        value="0.05924" />
      <inertia
        ixx="4.4262E-05"
        ixy="5.5113E-23"
        ixz="-2.9646E-21"
        iyy="4.0102E-05"
        iyz="-3.045E-21"
        izz="4.7957E-06" />
    </inertial>
    <visual>
      <origin
        xyz="0.234 -0.395 -0.144"
        rpy="0 -0.7854 1.5708" />
      <geometry>
        <mesh
          filename="package://robot_description/meshes/link7.STL" />
      </geometry>
      <material
        name="">
        <color
          rgba="0.89804 0.91765 0.92941 1" />
      </material>
    </visual>
    <collision>
      <origin
        xyz="0 0 0"
        rpy="0 0 0" />
      <geometry>
        <mesh
          filename="package://robot_description/meshes/link7.STL" />
      </geometry>
    </collision>
  </link>
  <joint
    name="joint 7"
    type="fixed">
    <origin
      xyz="-0.062994 0.061 -0.19179"
      rpy="0 0.7854 0" />
    <parent
      link="link4" />
    <child
      link="link7" />
    <axis
      xyz="0 0 0" />
  </joint>
  <link
    name="camera_mount_link">
    <inertial>
      <origin
        xyz="-0.0041238 -2.7756E-17 -0.004"
        rpy="0 0 0" />
      <mass
        value="0.05924" />
      <inertia
        ixx="4.0102E-05"
        ixy="-3.0489E-21"
        ixz="-5.0789E-23"
        iyy="4.7957E-06"
        iyz="0"
        izz="4.4262E-05" />
    </inertial>
    <visual>
      <origin
        xyz="0 0 0"
        rpy="0 0 0" />
      <geometry>
        <box size="0.001 0.001 0.001"/>
      </geometry>
      <material
        name="">
        <color
          rgba="0.89804 0.91765 0.92941 1" />
      </material>
    </visual>
    <collision>
      <origin
        xyz="0 0 0"
        rpy="0 0 0" />
      <geometry>
        <box size="0.001 0.001 0.001"/>
      </geometry>
    </collision>
  </link>
  <joint
    name="camera_mount_joint"
    type="fixed">
    <origin
      xyz="0 0 0"
      rpy="-1.5708 0 -1.5708" />
    <parent
      link="link7" />
    <child
      link="camera_mount_link" />
    <axis
      xyz="0 0 0" />
  </joint>
  <link
    name="camera_link">
    <inertial>
      <!-- this is original line xyz="-0.0050751 -8.3267E-17 -0.00875" -->
      <origin
        xyz="0 0 0"
        rpy="0 0 0" />
      <mass
        value="0.044809" />
      <inertia
        ixx="3.1898E-05"
        ixy="-3.5924E-21"
        ixz="-1.2952E-21"
        iyy="4.0973E-06"
        iyz="2.3293E-21"
        izz="3.3708E-05" />
    </inertial>
    <visual>
      <origin
        xyz="0.395 -0.145 -0.2335"
        rpy="0 0.7854 1.5708" />
      <geometry>
        <mesh
          filename="package://robot_description/meshes/camera_link.STL" />
      </geometry>
      <material
        name="">
        <color
          rgba="1 1 1 1" />
      </material>
    </visual>
    <collision>
      <origin
        xyz="0 0 0"
        rpy="0 0 0" />
      <geometry>
        <mesh
          filename="package://robot_description/meshes/camera_link.STL" />
      </geometry>
    </collision>
  </link>
  <joint
    name="camera_link_joint"
    type="fixed">
    <origin
      xyz="0.016845 0.100461 -0.077129"
      rpy="1.5708 0.785398 0" />
    <parent
      link="yanthra_link" />
    <child
      link="camera_link" />
    <axis
      xyz="0 0 0" />
  </joint>
  <link
    name="link3">
    <inertial>
      <origin
        xyz="-0.033163 -0.04027 -0.0050659"
        rpy="0 0 0" />
      <mass
        value="1.4316" />
      <inertia
        ixx="0.0037572"
        ixy="-0.00082268"
        ixz="-0.0011479"
        iyy="0.043868"
        iyz="-0.00017008"
        izz="0.044751" />
    </inertial>
    <visual>
      <origin
        xyz="0.069 -0.378 -0.330"
        rpy="0 0 0" />
      <geometry>
        <mesh
          filename="package://robot_description/meshes/link3.STL" />
      </geometry>
      <material
        name="">
        <color
          rgba="0.592156862745098 0.79607843137255 0.233333333333333 1" />
      </material>
    </visual>
    <collision>
      <origin
        xyz="0 0 0"
        rpy="0 0 0" />
      <geometry>
        <mesh
          filename="package://robot_description/meshes/link3.STL" />
      </geometry>
    </collision>
  </link>
  <joint
    name="joint 3"
    type="revolute">
    <origin
      xyz="-0.0675 0.042 -0.127"
      rpy="0 0.0063952 0" />
    <parent
      link="link4" />
    <child
      link="link3" />
    <axis
      xyz="0 -1 0" />
    <limit
      lower="-1.5708"
      upper="0.0"
      effort="0"
      velocity="0" />
  </joint>
  <link
    name="yanthra_link">
    <inertial>
      <origin
        xyz="-0.033163 0.04173 -0.0050659"
        rpy="0 0 0" />
      <mass
        value="1.4316" />
      <inertia
        ixx="0.0037572"
        ixy="-0.00082268"
        ixz="-0.0011479"
        iyy="0.043868"
        iyz="-0.00017008"
        izz="0.044751" />
    </inertial>
    <visual>
      <origin
        xyz="0 0 0"
        rpy="0 0 0" />
      <geometry>
        <box size="0.001 0.001 0.001"/>
      </geometry>
      <material
        name="">
        <color
          rgba="0.89804 0.91765 0.92941 1" />
      </material>
    </visual>
    <collision>
      <origin
        xyz="0 0 0"
        rpy="0 0 0" />
      <geometry>
        <box size="0.001 0.001 0.001"/>
      </geometry>
    </collision>
  </link>
  <joint
    name="yantra_joint"
    type="fixed">
    <origin
      xyz="0 -0.082 0"
      rpy="0 0 0" />
    <parent
      link="link3" />
    <child
      link="yanthra_link" />
    <axis
      xyz="0 0 0" />
  </joint>
  <link
    name="link5_origin">
    <inertial>
      <origin
        xyz="-0.033163 0.04173 -0.0050659"
        rpy="0 0 0" />
      <mass
        value="1.4316" />
      <inertia
        ixx="0.0037572"
        ixy="-0.00082268"
        ixz="-0.0011479"
        iyy="0.043868"
        iyz="-0.00017008"
        izz="0.044751" />
    </inertial>
    <visual>
      <origin
        xyz="0 0 0"
        rpy="0 0 0" />
      <geometry>
        <box size="0.001 0.001 0.001"/>
      </geometry>
      <material
        name="">
        <color
          rgba="0.89804 0.91765 0.92941 1" />
      </material>
    </visual>
    <collision>
      <origin
        xyz="0 0 0"
        rpy="0 0 0" />
      <geometry>
        <box size="0.001 0.001 0.001"/>
      </geometry>
    </collision>
  </link>
  <joint
    name="link5_origin_joint"
    type="fixed">
    <origin
      xyz="0 0 0"
      rpy="0 0 0" />
    <parent
      link="yanthra_link" />
    <child
      link="link5_origin" />
    <axis
      xyz="0 0 0" />
  </joint>
  <link
    name="link5">
    <inertial>
      <origin
        xyz="-0.24702 0.0038414 0.0022102"
        rpy="0 0 0" />
      <mass
        value="0.50477" />
      <inertia
        ixx="0.00073373"
        ixy="0.00051748"
        ixz="-0.00013446"
        iyy="0.014642"
        iyz="4.7355E-06"
        izz="0.014712" />
    </inertial>
    <visual>
      <origin
        xyz="-0.209 -0.300 -0.329"
        rpy="0 0 0" />
      <geometry>
        <mesh
          filename="package://robot_description/meshes/link5.STL" />
      </geometry>
      <material
        name="">
        <color
          rgba="0.25 0.28 0.3 1" />
      </material>
    </visual>
    <collision>
      <origin
        xyz="0 0 0"
        rpy="0 0 0" />
      <geometry>
        <mesh
          filename="package://robot_description/meshes/link5.STL" />
      </geometry>
    </collision>
  </link>
  <joint
    name="joint 5"
    type="prismatic">
    <origin
      xyz="0.27774 0.00375 -0.001"
      rpy="0 0 0" />
    <parent
      link="link5_origin" />
    <child
      link="link5" />
    <axis
      xyz="1 0 0" />
    <limit
      lower="0"
      upper="0.450"
      effort="0"
      velocity="0" />
  </joint>
  <link
    name="ee_link">
    <inertial>
      <origin
        xyz="-0.24702 0.0038414 0.0022102"
        rpy="0 0 0" />
      <mass
        value="0.50477" />
      <inertia
        ixx="0.00073373"
        ixy="0.00051748"
        ixz="-0.00013446"
        iyy="0.014642"
        iyz="4.7355E-06"
        izz="0.014712" />
    </inertial>
    <visual>
      <origin
        xyz="0 0 0"
        rpy="0 0 0" />
      <geometry>
        <box size="0.001 0.001 0.001"/>
      </geometry>
      <material
        name="">
        <color
          rgba="1 1 1 1" />
      </material>
    </visual>
    <collision>
      <origin
        xyz="0 0 0"
        rpy="0 0 0" />
      <geometry>
        <box size="0.001 0.001 0.001"/>
      </geometry>
    </collision>
  </link>
  <joint
    name="ee_joint"
    type="fixed">
    <origin
      xyz="0 0 0"
      rpy="0 0 0" />
    <parent
      link="link5" />
    <child
      link="ee_link" />
    <axis
      xyz="0 0 0" />
  </joint>
</robot>
