<?xml version='1.0' encoding='utf-8'?>
<robot name="vehicle">
    <!-- Gazebo Plugins -->
    <gazebo>
        <!-- Joint State Publisher -->
        <plugin filename="gz-sim-joint-state-publisher-system" name="gz::sim::systems::JointStatePublisher">
            <topic>joint_states</topic>
        </plugin>
        
        <!-- Joint Position Controller for steering -->
        <plugin filename="gz-sim-joint-position-controller-system" name="gz::sim::systems::JointPositionController">
            <joint_name>base-plate-front_Revolute-14</joint_name>
            <topic>/steering/front</topic>
            <p_gain>200</p_gain>
            <i_gain>20</i_gain>
            <d_gain>0.5</d_gain>
            <effort_limit>100</effort_limit>
        </plugin>
        
        <!-- NOTE: The CAD-exported joint names "left"/"right" are physically swapped -->
        <!-- relative to the robot's actual left/right sides. We correct this by   -->
        <!-- cross-wiring: /steering/left topic → right URDF joint and vice versa. -->
        <plugin filename="gz-sim-joint-position-controller-system" name="gz::sim::systems::JointPositionController">
            <joint_name>base-plate-right_Revolute-18</joint_name>
            <topic>/steering/left</topic>
            <p_gain>200</p_gain>
            <i_gain>20</i_gain>
            <d_gain>0.5</d_gain>
            <effort_limit>100</effort_limit>
        </plugin>
        
        <plugin filename="gz-sim-joint-position-controller-system" name="gz::sim::systems::JointPositionController">
            <joint_name>base-plate-left_Revolute-20</joint_name>
            <topic>/steering/right</topic>
            <p_gain>200</p_gain>
            <i_gain>20</i_gain>
            <d_gain>0.5</d_gain>
            <effort_limit>100</effort_limit>
        </plugin>
        
        <!-- Joint Velocity Controller for wheel rotation (force mode with PID) -->
        <!-- Using force mode because velocity mode's DART SERVO constraint -->
        <!-- fails to overcome ground contact forces with heavy robot (136kg) -->
        <plugin filename="gz-sim-joint-controller-system" name="gz::sim::systems::JointController">
            <joint_name>axial-front_Revolute-10</joint_name>
            <topic>/wheel/front/velocity</topic>
            <use_force_commands>true</use_force_commands>
            <p_gain>200</p_gain>
            <i_gain>20</i_gain>
            <d_gain>0.5</d_gain>
            <i_max>100</i_max>
            <i_min>-100</i_min>
            <cmd_max>2000</cmd_max>
            <cmd_min>-2000</cmd_min>
        </plugin>
        
        <!-- NOTE: Cross-wired to match steering swap above -->
        <!-- URDF "right" joint is physically LEFT → listens on /wheel/left/velocity -->
        <plugin filename="gz-sim-joint-controller-system" name="gz::sim::systems::JointController">
            <joint_name>axial-right_Revolute-19</joint_name>
            <topic>/wheel/left/velocity</topic>
            <use_force_commands>true</use_force_commands>
            <p_gain>200</p_gain>
            <i_gain>20</i_gain>
            <d_gain>0.5</d_gain>
            <i_max>100</i_max>
            <i_min>-100</i_min>
            <cmd_max>2000</cmd_max>
            <cmd_min>-2000</cmd_min>
        </plugin>
        
        <!-- URDF "left" joint is physically RIGHT → listens on /wheel/right/velocity -->
        <plugin filename="gz-sim-joint-controller-system" name="gz::sim::systems::JointController">
            <joint_name>axial-left_Revolute-21</joint_name>
            <topic>/wheel/right/velocity</topic>
            <use_force_commands>true</use_force_commands>
            <p_gain>200</p_gain>
            <i_gain>20</i_gain>
            <d_gain>0.5</d_gain>
            <i_max>100</i_max>
            <i_min>-100</i_min>
            <cmd_max>2000</cmd_max>
            <cmd_min>-2000</cmd_min>
        </plugin>
        <!-- Odometry Publisher -->
        <plugin filename="gz-sim-odometry-publisher-system" name="gz::sim::systems::OdometryPublisher">
            <odom_frame>odom</odom_frame>
            <robot_base_frame>base-v1</robot_base_frame>
            <odom_topic>odom</odom_topic>
            <tf_topic>tf</tf_topic>
            <odom_publish_frequency>50</odom_publish_frequency>
        </plugin>
    </gazebo>

    <!-- Material Colors for Gazebo -->
    <gazebo reference="base-v1">
        <visual>
            <material>
                <ambient>0.2 0.2 0.8 1</ambient>
                <diffuse>0.2 0.2 0.8 1</diffuse>
            </material>
        </visual>
    </gazebo>
    
    <gazebo reference="front-wheel">
        <visual>
            <material>
                <ambient>0.1 0.1 0.1 1</ambient>
                <diffuse>0.1 0.1 0.1 1</diffuse>
            </material>
        </visual>
        <mu1>1.0</mu1>
        <mu2>1.0</mu2>
    </gazebo>
    
    <gazebo reference="left-wheel">
        <visual>
            <material>
                <ambient>0.1 0.1 0.1 1</ambient>
                <diffuse>0.1 0.1 0.1 1</diffuse>
            </material>
        </visual>
        <mu1>1.0</mu1>
        <mu2>1.0</mu2>
    </gazebo>
    
    <gazebo reference="right-wheel">
        <visual>
            <material>
                <ambient>0.1 0.1 0.1 1</ambient>
                <diffuse>0.1 0.1 0.1 1</diffuse>
            </material>
        </visual>
        <mu1>1.0</mu1>
        <mu2>1.0</mu2>
    </gazebo>

    <gazebo reference="axial-front">
        <visual>
            <material>
                <ambient>0.5 0.5 0.5 1</ambient>
                <diffuse>0.5 0.5 0.5 1</diffuse>
            </material>
        </visual>
    </gazebo>

    <gazebo reference="axial-left">
        <visual>
            <material>
                <ambient>0.5 0.5 0.5 1</ambient>
                <diffuse>0.5 0.5 0.5 1</diffuse>
            </material>
        </visual>
    </gazebo>

    <gazebo reference="axial-right">
        <visual>
            <material>
                <ambient>0.5 0.5 0.5 1</ambient>
                <diffuse>0.5 0.5 0.5 1</diffuse>
            </material>
        </visual>
    </gazebo>

    <link name="base-v1">
        <inertial>
            <origin xyz="0.6500001868886057 1.1614430069425479 0.8999355832154555" rpy="0.0 0.0 0.0" />
            <mass value="136.24259912896545" />
            <inertia ixx="47.31920257106103" iyy="75.876166759452" izz="51.38395890485235" ixy="2.8549514440756267e-05" iyz="0.0017393470290161441" ixz="1.6126433935721856e-05" />
        </inertial>
        <visual name="base-v1_visual">
            <origin xyz="0.0 0.0 0.0" rpy="0.0 0.0 0.0" />
            <geometry>
                <mesh filename="package://vehicle_control/meshes/base-v1.stl" scale="0.001 0.001 0.001" />
            </geometry>
        </visual>
        <collision name="base-v1_collision">
            <origin xyz="0.0 0.0 0.0" rpy="0.0 0.0 0.0" />
            <geometry>
                <mesh filename="package://vehicle_control/meshes/base-v1.stl" scale="0.001 0.001 0.001" />
            </geometry>
        </collision>
    </link>
    
    <!-- Kinematic Origin Link - Robot Center for Velocity Kinematics -->
    <link name="origin">
        <inertial>
            <origin xyz="0.0 0.0 0.0" rpy="0.0 0.0 0.0" />
            <mass value="0.001" />
            <inertia ixx="0.0001" iyy="0.0001" izz="0.0001" ixy="0.0" iyz="0.0" ixz="0.0" />
        </inertial>
    </link>
    
    <link name="axial-front">
        <inertial>
            <origin xyz="-0.026560272848659566 -0.008141810073088198 -0.18243738480233973" rpy="0.0 -0.0 0.0" />
            <mass value="5.960125317942265" />
            <inertia ixx="0.19349834660830645" iyy="0.1595327515084719" izz="0.07140362306565073" ixy="-0.0012161665935744859" iyz="-0.0014155363552110778" ixz="0.011255587512742693" />
        </inertial>
        <visual name="axial-front_visual">
            <origin xyz="1.5762222460580233e-09 -0.12399999984744633 -0.41923332741968056" rpy="1.5707963267948963 4.0059997780420813e-16 1.5707963267948974" />
            <geometry>
                <mesh filename="package://vehicle_control/meshes/axial-front.stl" scale="0.001 0.001 0.001" />
            </geometry>
        </visual>
        <collision name="axial-front_collision">
            <origin xyz="1.5762222460580233e-09 -0.12399999984744633 -0.41923332741968056" rpy="1.5707963267948963 4.0059997780420813e-16 1.5707963267948974" />
            <geometry>
                <mesh filename="package://vehicle_control/meshes/axial-front.stl" scale="0.001 0.001 0.001" />
            </geometry>
        </collision>
    </link>
    <link name="front-wheel">
        <inertial>
            <origin xyz="-0.010233905818133292 -2.4703738389888486e-05 4.411287449954671e-06" rpy="0.0 -0.0 0.0" />
            <mass value="17.643705645291966" />
            <inertia ixx="0.8667565646974538" iyy="0.4577948441505626" izz="0.45785195086842734" ixy="1.934603872988383e-05" iyz="3.374767061359307e-07" ixz="1.438798709951783e-06" />
        </inertial>
        <visual name="front-wheel_visual">
            <origin xyz="-0.010194000152553855 -2.729718033833706e-09 1.120952219935134e-12" rpy="3.078915428290348 -8.637729329052633e-16 -4.626660393294165e-16" />
            <geometry>
                <mesh filename="package://vehicle_control/meshes/front-wheel.stl" scale="0.001 0.001 0.001" />
            </geometry>
        </visual>
        <collision name="front-wheel_collision">
            <origin xyz="-0.010194000152553855 -2.729718033833706e-09 1.120952219935134e-12" rpy="3.078915428290348 -8.637729329052633e-16 -4.626660393294165e-16" />
            <geometry>
                <mesh filename="package://vehicle_control/meshes/front-wheel.stl" scale="0.001 0.001 0.001" />
            </geometry>
            <surface>
                <friction>
                    <ode>
                        <mu>1.0</mu>
                        <mu2>1.0</mu2>
                    </ode>
                </friction>
            </surface>
        </collision>
    </link>
    <link name="base-plate-right">
        <inertial>
            <origin xyz="0.0019345853682676407 0.00018424622798065117 -0.04849999833376195" rpy="0.0 -2.4015000221239154e-49 0.0" />
            <mass value="20.286776465465465" />
            <inertia ixx="0.03718710610497311" iyy="0.14633477738252054" izz="0.15170883686023018" ixy="0.00039969569730757826" iyz="3.78014842524293e-19" ixz="4.529632743283801e-18" />
        </inertial>
        <visual name="base-plate-right_visual">
            <origin xyz="1.5762218552595187e-09 1.5254542518050585e-10 1.6662379209719803e-09" rpy="1.5707963267948974 2.4286128663675117e-16 9.057424948943896e-16" />
            <geometry>
                <mesh filename="package://vehicle_control/meshes/base-plate-right.stl" scale="0.001 0.001 0.001" />
            </geometry>
        </visual>
        <collision name="base-plate-right_collision">
            <origin xyz="1.5762218552595187e-09 1.5254542518050585e-10 1.6662379209719803e-09" rpy="1.5707963267948974 2.4286128663675117e-16 9.057424948943896e-16" />
            <geometry>
                <mesh filename="package://vehicle_control/meshes/base-plate-right.stl" scale="0.001 0.001 0.001" />
            </geometry>
        </collision>
    </link>
    <link name="base-plate-front">
        <inertial>
            <origin xyz="-0.0019167896688466613 -0.00018255139459364856 -0.04849999833376153" rpy="0.0 -4.722979357162093e-94 0.0" />
            <mass value="20.47508775142214" />
            <inertia ixx="0.03739180366840156" iyy="0.1465401669057158" izz="0.15182362046475362" ixy="0.00039962919299529887" iyz="5.639932965095795e-14" ixz="-9.592326932761353e-14" />
        </inertial>
        <visual name="base-plate-front_visual">
            <origin xyz="-1.299999998423785 0.9000000001525496 1.6662405499801026e-09" rpy="1.5707963267948972 1.28889954265076e-15 9.057424948943894e-16" />
            <geometry>
                <mesh filename="package://vehicle_control/meshes/base-plate-front.stl" scale="0.001 0.001 0.001" />
            </geometry>
        </visual>
        <collision name="base-plate-front_collision">
            <origin xyz="-1.299999998423785 0.9000000001525496 1.6662405499801026e-09" rpy="1.5707963267948972 1.28889954265076e-15 9.057424948943894e-16" />
            <geometry>
                <mesh filename="package://vehicle_control/meshes/base-plate-front.stl" scale="0.001 0.001 0.001" />
            </geometry>
        </collision>
    </link>
    <link name="base-plate-left">
        <inertial>
            <origin xyz="0.0019345853682708736 -0.00018424622799429358 0.048499998333762874" rpy="0.0 4.722979357162093e-94 0.0" />
            <mass value="20.286776465465472" />
            <inertia ixx="0.037187106106497225" iyy="0.14633477738251344" izz="0.1517088368611823" ixy="-0.0003996956972720511" iyz="4.618527782440651e-14" ixz="-3.4772185131259903e-13" />
        </inertial>
        <visual name="base-plate-left_visual">
            <origin xyz="1.5762219263137923e-09 -1.8000000001525343 -1.6662374946463389e-09" rpy="-1.5707963267948963 5.703770789011712e-15 -9.05742494894392e-16" />
            <geometry>
                <mesh filename="package://vehicle_control/meshes/base-plate-left.stl" scale="0.001 0.001 0.001" />
            </geometry>
        </visual>
        <collision name="base-plate-left_collision">
            <origin xyz="1.5762219263137923e-09 -1.8000000001525343 -1.6662374946463389e-09" rpy="-1.5707963267948963 5.703770789011712e-15 -9.05742494894392e-16" />
            <geometry>
                <mesh filename="package://vehicle_control/meshes/base-plate-left.stl" scale="0.001 0.001 0.001" />
            </geometry>
        </collision>
    </link>
    <link name="right-wheel">
        <inertial>
            <origin xyz="0.08976609726381397 2.4926996962761906e-05 -2.8554460971186304e-06" rpy="0.0 -0.0 0.0" />
            <mass value="17.643705645291966" />
            <inertia ixx="0.8667565646974431" iyy="0.4577950260034438" izz="0.45785176901554436" ixy="-1.9217930463000243e-05" iyz="-3.2350953147464168e-06" ixz="-2.6477357955023706e-06" />
        </inertial>
        <visual name="right-wheel_visual">
            <origin xyz="0.08980600292939343 -1.8156377734612762e-09 1.1196021887371898e-12" rpy="8.673617379882857e-17 -3.897623472656189e-15 3.671090234079189e-15" />
            <geometry>
                <mesh filename="package://vehicle_control/meshes/right-wheel.stl" scale="0.001 0.001 0.001" />
            </geometry>
        </visual>
        <collision name="right-wheel_collision">
            <origin xyz="0.08980600292939343 -1.8156377734612762e-09 1.1196021887371898e-12" rpy="8.673617379882857e-17 -3.897623472656189e-15 3.671090234079189e-15" />
            <geometry>
                <mesh filename="package://vehicle_control/meshes/right-wheel.stl" scale="0.001 0.001 0.001" />
            </geometry>
            <surface>
                <friction>
                    <ode>
                        <mu>1.0</mu>
                        <mu2>1.0</mu2>
                    </ode>
                </friction>
            </surface>
        </collision>
    </link>
    <link name="axial-right">
        <inertial>
            <origin xyz="-0.026560272848659708 0.008141810073096422 0.18320405571641943" rpy="0.0 -0.0 -2.189528850507527e-47" />
            <mass value="5.960125317942265" />
            <inertia ixx="0.19349834660831705" iyy="0.15953275150846125" izz="0.07140362306564982" ixy="0.001216166593576262" iyz="-0.0014155363552106335" ixz="-0.011255587512739636" />
        </inertial>
        <visual name="axial-right_visual">
            <origin xyz="1.5762225125115492e-09 0.12399999984745406 0.4199999983337595" rpy="-1.5707963267948968 1.155743137021616e-15 -1.5707963267949006" />
            <geometry>
                <mesh filename="package://vehicle_control/meshes/axial-right.stl" scale="0.001 0.001 0.001" />
            </geometry>
        </visual>
        <collision name="axial-right_collision">
            <origin xyz="1.5762225125115492e-09 0.12399999984745406 0.4199999983337595" rpy="-1.5707963267948968 1.155743137021616e-15 -1.5707963267949006" />
            <geometry>
                <mesh filename="package://vehicle_control/meshes/axial-right.stl" scale="0.001 0.001 0.001" />
            </geometry>
        </collision>
    </link>
    <link name="axial-left">
        <inertial>
            <origin xyz="-0.02656027284865676 -0.00814181007308335 -0.18243738480234142" rpy="0.0 -0.0 0.0" />
            <mass value="5.960125317942265" />
            <inertia ixx="0.19349834660832066" iyy="0.15953275150846302" izz="0.07140362306564718" ixy="-0.0012161665935745969" iyz="-0.0014155363552097455" ixz="0.011255587512739751" />
        </inertial>
        <visual name="axial-left_visual">
            <origin xyz="1.5762251415196715e-09 -0.12399999984744099 -0.41923332741968167" rpy="1.5707963267948966 -4.216670939182494e-16 1.5707963267948974" />
            <geometry>
                <mesh filename="package://vehicle_control/meshes/axial-left.stl" scale="0.001 0.001 0.001" />
            </geometry>
        </visual>
        <collision name="axial-left_collision">
            <origin xyz="1.5762251415196715e-09 -0.12399999984744099 -0.41923332741968167" rpy="1.5707963267948966 -4.216670939182494e-16 1.5707963267948974" />
            <geometry>
                <mesh filename="package://vehicle_control/meshes/axial-left.stl" scale="0.001 0.001 0.001" />
            </geometry>
        </collision>
    </link>
    <link name="left-wheel">
        <inertial>
            <origin xyz="0.08976609726380005 2.4926082885201596e-05 -2.855446092233649e-06" rpy="-3.323448711015614e-63 -0.0 0.0" />
            <mass value="17.643705645291966" />
            <inertia ixx="0.86675656469744" iyy="0.4577950260034491" izz="0.4578517690155408" ixy="-1.9217930464776604e-05" iyz="-3.2350953143023276e-06" ixz="-2.647735797722817e-06" />
        </inertial>
        <visual name="left-wheel_visual">
            <origin xyz="0.0898060029293795 -2.72971533377131e-09 1.1244694064771465e-12" rpy="-5.693600210639377e-16 -1.0824674490095377e-15 7.460184898525892e-15" />
            <geometry>
                <mesh filename="package://vehicle_control/meshes/left-wheel.stl" scale="0.001 0.001 0.001" />
            </geometry>
        </visual>
        <collision name="left-wheel_collision">
            <origin xyz="0.0898060029293795 -2.72971533377131e-09 1.1244694064771465e-12" rpy="-5.693600210639377e-16 -1.0824674490095377e-15 7.460184898525892e-15" />
            <geometry>
                <mesh filename="package://vehicle_control/meshes/left-wheel.stl" scale="0.001 0.001 0.001" />
            </geometry>
            <surface>
                <friction>
                    <ode>
                        <mu>1.0</mu>
                        <mu2>1.0</mu2>
                    </ode>
                </friction>
            </surface>
        </collision>
    </link>
    <joint name="axial-front_Revolute-10" type="continuous">
        <origin xyz="4.806000000002087e-05 -0.00799999999999999 -0.3992317399999999" rpy="-1.5707963267948966 -4.8862532784603164e-32 -1.5707963267948966" />
        <parent link="axial-front" />
        <child link="front-wheel" />
        <axis xyz="-1.0 -4.974508036802331e-32 -0.0" />
        <dynamics damping="0.5" friction="0.1" />
        <limit effort="500" velocity="20.0" />
    </joint>
    
    <!-- Kinematic Origin Joint - Defines Robot Center -->
    <!-- From base-v1 (at right wheel 0,0,0) to robot center (0.65, 0.9, 0) -->
    <!-- base-v1 at right wheel: (0, 0, 0)
         rear axle center: (0, 0.9) = midpoint of left(0,1.8) and right(0,0)
         front wheel: (1.3, 0.9)
         robot center: (0.65, 0.9) = midpoint of front and rear axle -->
    <joint name="base-v1_to_origin" type="fixed">
        <origin xyz="0.65 0.0 0.9" rpy="-1.5707963267948966 0.0 0.0" />
        <parent link="base-v1" />
        <child link="origin" />
    </joint>
    
    <joint name="base-v1_Rigid-11" type="fixed">
        <origin xyz="1.2999999984237778 -1.6662377078091596e-09 0.900000000152554" rpy="-1.5707963267948961 -9.057424948943961e-16 -2.0816681711721774e-16" />
        <parent link="base-v1" />
        <child link="base-plate-front" />
    </joint>
    <joint name="base-v1_Rigid-12" type="fixed">
        <origin xyz="-1.5762218197323818e-09 -1.6662379209719803e-09 1.5254542518050585e-10" rpy="-1.5707963267948961 -9.057424948943961e-16 -2.0816681711721774e-16" />
        <parent link="base-v1" />
        <child link="base-plate-right" />
    </joint>
    <joint name="base-v1_Rigid-13" type="fixed">
        <origin xyz="-1.5762245908490514e-09 -1.6662371393749709e-09 1.8000000001525605" rpy="1.570796326794897 -9.057424948943961e-16 -2.0816681711721774e-16" />
        <parent link="base-v1" />
        <child link="base-plate-left" />
    </joint>
    <joint name="base-plate-front_Revolute-14" type="revolute">
        <origin xyz="0.105 0.01 -0.09700000000000003" rpy="2.3948350467888256e-63 2.237605975518999e-31 0.0" />
        <parent link="base-plate-front" />
        <child link="axial-front" />
        <axis xyz="-2.3590385388993773e-31 0.0 1.0" />
        <limit lower="-1.570796" upper="1.570796" effort="100" velocity="2.0" />
        <dynamics damping="1.0" friction="0.5" />
    </joint>
    <joint name="base-plate-right_Revolute-18" type="revolute">
        <origin xyz="-0.10500000000000002 -0.01 -0.09699999999999996" rpy="3.141592653589793 -7.18779982929554e-32 2.189528850507527e-47" />
        <parent link="base-plate-right" />
        <child link="axial-right" />
        <axis xyz="-5.973474195491757e-32 0.0 0.9999999999999999" />
        <limit lower="-1.570796" upper="1.570796" effort="100" velocity="2.0" />
        <dynamics damping="1.0" friction="0.5" />
    </joint>
    <joint name="axial-right_Revolute-19" type="continuous">
        <origin xyz="4.80600000000031e-05 -0.09219303999999993 0.3999984099999999" rpy="1.5707963267948966 -1.4612587475429843e-32 1.5707963267948966" />
        <parent link="axial-right" />
        <child link="right-wheel" />
        <axis xyz="-1.0 1.1276818820434178e-31 -7.888609052210118e-31" />
        <dynamics damping="0.5" friction="0.1" />
        <limit effort="500" velocity="20.0" />
    </joint>
    <joint name="base-plate-left_Revolute-20" type="revolute">
        <origin xyz="-0.10500000000000002 0.01 0.09700000000000003" rpy="-3.141592653589793 -2.9112058178301707e-31 1.9721522630525295e-31" />
        <parent link="base-plate-left" />
        <child link="axial-left" />
        <axis xyz="-3.032638381210549e-31 0.0 1.0" />
        <limit lower="-1.570796" upper="1.570796" effort="100" velocity="2.0" />
        <dynamics damping="1.0" friction="0.5" />
    </joint>
    <joint name="axial-left_Revolute-21" type="continuous">
        <origin xyz="4.80600000000031e-05 0.09219303999999993 -0.3992317399999999" rpy="-1.5707963267948966 -1.812345601166459e-34 -1.5707963267948966" />
        <parent link="axial-left" />
        <child link="left-wheel" />
        <axis xyz="-1.0000000000000002 3.370377402677343e-32 9.860761315262648e-32" />
        <dynamics damping="0.5" friction="0.1" />
        <limit effort="500" velocity="20.0" />
    </joint>

    <!-- ==================== SENSOR LINKS ==================== -->
    
    <!-- IMU Sensor -->
    <link name="imu_link">
        <inertial>
            <origin xyz="0 0 0" rpy="0 0 0"/>
            <mass value="0.001"/>
            <inertia ixx="0.0001" iyy="0.0001" izz="0.0001" ixy="0" iyz="0" ixz="0"/>
        </inertial>
    </link>
    
    <joint name="imu_joint" type="fixed">
        <origin xyz="0.65 0.0 0.9" rpy="-1.5707963267948966 0.0 0.0"/>
        <parent link="base-v1"/>
        <child link="imu_link"/>
    </joint>
    
    <gazebo reference="imu_link">
        <sensor name="imu_sensor" type="imu">
            <always_on>true</always_on>
            <update_rate>100</update_rate>
            <topic>imu</topic>
            <imu>
                <angular_velocity>
                    <x><noise type="none"/></x>
                    <y><noise type="none"/></y>
                    <z><noise type="none"/></z>
                </angular_velocity>
                <linear_acceleration>
                    <x><noise type="none"/></x>
                    <y><noise type="none"/></y>
                    <z><noise type="none"/></z>
                </linear_acceleration>
            </imu>
        </sensor>
    </gazebo>

    <!-- NavSat/GPS Sensor -->
    <link name="navsat_link">
        <inertial>
            <origin xyz="0 0 0" rpy="0 0 0"/>
            <mass value="0.001"/>
            <inertia ixx="0.0001" iyy="0.0001" izz="0.0001" ixy="0" iyz="0" ixz="0"/>
        </inertial>
    </link>
    
    <joint name="navsat_joint" type="fixed">
        <origin xyz="0.65 0.0 1.2" rpy="-1.5707963267948966 0.0 0.0"/>
        <parent link="base-v1"/>
        <child link="navsat_link"/>
    </joint>
    
    <gazebo reference="navsat_link">
        <sensor name="navsat_sensor" type="navsat">
            <always_on>true</always_on>
            <update_rate>10</update_rate>
            <topic>navsat</topic>
        </sensor>
    </gazebo>

    <!-- Camera Sensor (front-facing, simulating OAK-D Lite) -->
    <link name="camera_link">
        <inertial>
            <origin xyz="0 0 0" rpy="0 0 0"/>
            <mass value="0.001"/>
            <inertia ixx="0.0001" iyy="0.0001" izz="0.0001" ixy="0" iyz="0" ixz="0"/>
        </inertial>
    </link>
    
    <link name="camera_optical_link">
        <inertial>
            <origin xyz="0 0 0" rpy="0 0 0"/>
            <mass value="0.001"/>
            <inertia ixx="0.0001" iyy="0.0001" izz="0.0001" ixy="0" iyz="0" ixz="0"/>
        </inertial>
    </link>
    
    <!-- Camera mounted in front of front wheel, facing forward with 15° downward tilt -->
    <!-- base-v1 Z-axis = world lateral; X-forward, Y-up in Gazebo after roll correction -->
    <!-- Position: x=1.55 (ahead of front wheel at 1.4), z=0.9 (centerline), y height handled by rpy -->
    <joint name="camera_joint" type="fixed">
        <origin xyz="1.55 -0.25 0.9" rpy="-1.5707963267948966 0.0 -0.2618"/>
        <parent link="base-v1"/>
        <child link="camera_link"/>
    </joint>
    
    <joint name="camera_optical_joint" type="fixed">
        <origin xyz="0 0 0" rpy="-1.5707963267948966 0.0 -1.5707963267948966"/>
        <parent link="camera_link"/>
        <child link="camera_optical_link"/>
    </joint>
    
    <gazebo reference="camera_link">
        <sensor name="camera_sensor" type="camera">
            <always_on>true</always_on>
            <update_rate>10</update_rate>
            <visualize>true</visualize>
            <topic>front_camera</topic>
            <camera>
                <horizontal_fov>1.2740903539558606</horizontal_fov>
                <image>
                    <width>640</width>
                    <height>480</height>
                    <format>R8G8B8</format>
                </image>
                <clip>
                    <near>0.1</near>
                    <far>100</far>
                </clip>
            </camera>
        </sensor>
    </gazebo>
</robot>
