<?xml version="1.0" encoding="utf-8"?><robot name="vehicle_arm">
    <gazebo>
        <plugin filename="gz-sim-joint-state-publisher-system" name="gz::sim::systems::JointStatePublisher">
            <topic>joint_states</topic>
        </plugin>
        <plugin filename="gz-sim-joint-position-controller-system" name="gz::sim::systems::JointPositionController">
            <joint_name>base-plate-front_Revolute-14</joint_name>
            <topic>/steering/front</topic>
            <p_gain>200</p_gain>
            <i_gain>20</i_gain>
            <d_gain>0.5</d_gain>
            <effort_limit>100</effort_limit>
        </plugin>
        <plugin filename="gz-sim-joint-position-controller-system" name="gz::sim::systems::JointPositionController">
            <joint_name>base-plate-right_Revolute-18</joint_name>
            <topic>/steering/left</topic>
            <p_gain>200</p_gain>
            <i_gain>20</i_gain>
            <d_gain>0.5</d_gain>
            <effort_limit>100</effort_limit>
        </plugin>
        <plugin filename="gz-sim-joint-position-controller-system" name="gz::sim::systems::JointPositionController">
            <joint_name>base-plate-left_Revolute-20</joint_name>
            <topic>/steering/right</topic>
            <p_gain>200</p_gain>
            <i_gain>20</i_gain>
            <d_gain>0.5</d_gain>
            <effort_limit>100</effort_limit>
        </plugin>
        <plugin filename="gz-sim-joint-controller-system" name="gz::sim::systems::JointController">
            <joint_name>axial-front_Revolute-10</joint_name>
            <topic>/wheel/front/velocity</topic>
            <use_force_commands>true</use_force_commands>
            <p_gain>200</p_gain>
            <i_gain>20</i_gain>
            <d_gain>0.5</d_gain>
            <i_max>100</i_max>
            <i_min>-100</i_min>
            <cmd_max>2000</cmd_max>
            <cmd_min>-2000</cmd_min>
        </plugin>
        <plugin filename="gz-sim-joint-controller-system" name="gz::sim::systems::JointController">
            <joint_name>axial-right_Revolute-19</joint_name>
            <topic>/wheel/left/velocity</topic>
            <use_force_commands>true</use_force_commands>
            <p_gain>200</p_gain>
            <i_gain>20</i_gain>
            <d_gain>0.5</d_gain>
            <i_max>100</i_max>
            <i_min>-100</i_min>
            <cmd_max>2000</cmd_max>
            <cmd_min>-2000</cmd_min>
        </plugin>
        <plugin filename="gz-sim-joint-controller-system" name="gz::sim::systems::JointController">
            <joint_name>axial-left_Revolute-21</joint_name>
            <topic>/wheel/right/velocity</topic>
            <use_force_commands>true</use_force_commands>
            <p_gain>200</p_gain>
            <i_gain>20</i_gain>
            <d_gain>0.5</d_gain>
            <i_max>100</i_max>
            <i_min>-100</i_min>
            <cmd_max>2000</cmd_max>
            <cmd_min>-2000</cmd_min>
        </plugin>
        <plugin filename="gz-sim-odometry-publisher-system" name="gz::sim::systems::OdometryPublisher">
            <odom_frame>odom</odom_frame>
            <robot_base_frame>base-v1</robot_base_frame>
            <odom_topic>odom</odom_topic>
            <tf_topic>tf</tf_topic>
            <odom_publish_frequency>50</odom_publish_frequency>
        </plugin>
    </gazebo>
    <gazebo reference="base-v1">
        <visual>
            <material>
                <ambient>0.2 0.2 0.8 1</ambient>
                <diffuse>0.2 0.2 0.8 1</diffuse>
            </material>
        </visual>
    </gazebo>
    <gazebo reference="front-wheel">
        <visual>
            <material>
                <ambient>0.0314 0.0275 0.0275 1</ambient>
                <diffuse>0.0314 0.0275 0.0275 1</diffuse>
            </material>
        </visual>
        <mu1>1.0</mu1>
        <mu2>1.0</mu2>
    </gazebo>
    <gazebo reference="left-wheel">
        <visual>
            <material>
                <ambient>0.0314 0.0275 0.0275 1</ambient>
                <diffuse>0.0314 0.0275 0.0275 1</diffuse>
            </material>
        </visual>
        <mu1>1.0</mu1>
        <mu2>1.0</mu2>
    </gazebo>
    <gazebo reference="right-wheel">
        <visual>
            <material>
                <ambient>0.0863 0.0745 0.0745 1</ambient>
                <diffuse>0.0863 0.0745 0.0745 1</diffuse>
            </material>
        </visual>
        <mu1>1.0</mu1>
        <mu2>1.0</mu2>
    </gazebo>
    <gazebo reference="axial-front">
        <visual>
            <material>
                <ambient>0.5 0.5 0.5 1</ambient>
                <diffuse>0.5 0.5 0.5 1</diffuse>
            </material>
        </visual>
    </gazebo>
    <gazebo reference="axial-left">
        <visual>
            <material>
                <ambient>0.5 0.5 0.5 1</ambient>
                <diffuse>0.5 0.5 0.5 1</diffuse>
            </material>
        </visual>
    </gazebo>
    <gazebo reference="axial-right">
        <visual>
            <material>
                <ambient>0.5 0.5 0.5 1</ambient>
                <diffuse>0.5 0.5 0.5 1</diffuse>
            </material>
        </visual>
    </gazebo>
    <link name="base-v1">
        <inertial>
            <origin xyz="0.6500001868886057 1.1614430069425479 0.8999355832154555" rpy="0.0 0.0 0.0"/>
            <mass value="136.24259912896545"/>
            <inertia ixx="47.31920257106103" iyy="75.876166759452" izz="51.38395890485235" ixy="2.8549514440756267e-05" iyz="0.0017393470290161441" ixz="1.6126433935721856e-05"/>
        </inertial>
        <visual name="base-v1_visual">
            <origin xyz="0.0 0.0 0.0" rpy="0.0 0.0 0.0"/>
            <geometry>
                <mesh filename="package://vehicle_arm_sim/meshes/base-v1.stl" scale="0.001 0.001 0.001"/>
            </geometry>
        </visual>
        <collision name="base-v1_collision">
            <origin xyz="0.0 0.0 0.0" rpy="0.0 0.0 0.0"/>
            <geometry>
                <mesh filename="package://vehicle_arm_sim/meshes/base-v1.stl" scale="0.001 0.001 0.001"/>
            </geometry>
        </collision>
    </link>
    <link name="origin">
        <inertial>
            <origin xyz="0.0 0.0 0.0" rpy="0.0 0.0 0.0"/>
            <mass value="0.001"/>
            <inertia ixx="0.0001" iyy="0.0001" izz="0.0001" ixy="0.0" iyz="0.0" ixz="0.0"/>
        </inertial>
    </link>
    <link name="axial-front">
        <inertial>
            <origin xyz="-0.026560272848659566 -0.008141810073088198 -0.18243738480233973" rpy="0.0 -0.0 0.0"/>
            <mass value="5.960125317942265"/>
            <inertia ixx="0.19349834660830645" iyy="0.1595327515084719" izz="0.07140362306565073" ixy="-0.0012161665935744859" iyz="-0.0014155363552110778" ixz="0.011255587512742693"/>
        </inertial>
        <visual name="axial-front_visual">
            <origin xyz="1.5762222460580233e-09 -0.12399999984744633 -0.41923332741968056" rpy="1.5707963267948963 4.0059997780420813e-16 1.5707963267948974"/>
            <geometry>
                <mesh filename="package://vehicle_arm_sim/meshes/axial-front.stl" scale="0.001 0.001 0.001"/>
            </geometry>
        </visual>
        <collision name="axial-front_collision">
            <origin xyz="1.5762222460580233e-09 -0.12399999984744633 -0.41923332741968056" rpy="1.5707963267948963 4.0059997780420813e-16 1.5707963267948974"/>
            <geometry>
                <mesh filename="package://vehicle_arm_sim/meshes/axial-front.stl" scale="0.001 0.001 0.001"/>
            </geometry>
        </collision>
    </link>
    <link name="front-wheel">
        <inertial>
            <origin xyz="-0.010233905818133292 -2.4703738389888486e-05 4.411287449954671e-06" rpy="0.0 -0.0 0.0"/>
            <mass value="17.643706"/>
            <inertia ixx="0.8667565646974538" iyy="0.4577948441505626" izz="0.45785195086842734" ixy="1.934603872988383e-05" iyz="3.374767061359307e-07" ixz="1.438798709951783e-06"/>
        </inertial>
        <visual name="front-wheel_visual">
            <origin xyz="-0.010194 0 0" rpy="3.078915 0 0"/>
            <geometry><mesh filename="package://vehicle_arm_sim/meshes/front-wheel.stl" scale="0.001 0.001 0.001"/></geometry>
            <material name="front-wheel_material_0">
                <color rgba="0.0314 0.0275 0.0275 1.0"/>
            </material>
        </visual>
        <collision name="front-wheel_collision">
            <origin xyz="-0.010194000152553855 -2.729718033833706e-09 1.120952219935134e-12" rpy="3.078915428290348 -8.637729329052633e-16 -4.626660393294165e-16"/>
            <geometry><mesh filename="package://vehicle_arm_sim/meshes/front-wheel.stl" scale="0.001 0.001 0.001"/></geometry>
            <surface>
                <friction>
                    <ode>
                        <mu>1.0</mu>
                        <mu2>1.0</mu2>
                    </ode>
                </friction>
            </surface>
        </collision>
    </link>
    <link name="base-plate-right">
        <inertial>
            <origin xyz="0.0019345853682676407 0.00018424622798065117 -0.04849999833376195" rpy="0.0 -2.4015000221239154e-49 0.0"/>
            <mass value="20.286776465465465"/>
            <inertia ixx="0.03718710610497311" iyy="0.14633477738252054" izz="0.15170883686023018" ixy="0.00039969569730757826" iyz="3.78014842524293e-19" ixz="4.529632743283801e-18"/>
        </inertial>
        <visual name="base-plate-right_visual">
            <origin xyz="1.5762218552595187e-09 1.5254542518050585e-10 1.6662379209719803e-09" rpy="1.5707963267948974 2.4286128663675117e-16 9.057424948943896e-16"/>
            <geometry>
                <mesh filename="package://vehicle_arm_sim/meshes/base-plate-right.stl" scale="0.001 0.001 0.001"/>
            </geometry>
        </visual>
        <collision name="base-plate-right_collision">
            <origin xyz="1.5762218552595187e-09 1.5254542518050585e-10 1.6662379209719803e-09" rpy="1.5707963267948974 2.4286128663675117e-16 9.057424948943896e-16"/>
            <geometry>
                <mesh filename="package://vehicle_arm_sim/meshes/base-plate-right.stl" scale="0.001 0.001 0.001"/>
            </geometry>
        </collision>
    </link>
    <link name="base-plate-front">
        <inertial>
            <origin xyz="-0.0019167896688466613 -0.00018255139459364856 -0.04849999833376153" rpy="0.0 -4.722979357162093e-94 0.0"/>
            <mass value="20.47508775142214"/>
            <inertia ixx="0.03739180366840156" iyy="0.1465401669057158" izz="0.15182362046475362" ixy="0.00039962919299529887" iyz="5.639932965095795e-14" ixz="-9.592326932761353e-14"/>
        </inertial>
        <visual name="base-plate-front_visual">
            <origin xyz="-1.299999998423785 0.9000000001525496 1.6662405499801026e-09" rpy="1.5707963267948972 1.28889954265076e-15 9.057424948943894e-16"/>
            <geometry>
                <mesh filename="package://vehicle_arm_sim/meshes/base-plate-front.stl" scale="0.001 0.001 0.001"/>
            </geometry>
        </visual>
        <collision name="base-plate-front_collision">
            <origin xyz="-1.299999998423785 0.9000000001525496 1.6662405499801026e-09" rpy="1.5707963267948972 1.28889954265076e-15 9.057424948943894e-16"/>
            <geometry>
                <mesh filename="package://vehicle_arm_sim/meshes/base-plate-front.stl" scale="0.001 0.001 0.001"/>
            </geometry>
        </collision>
    </link>
    <link name="base-plate-left">
        <inertial>
            <origin xyz="0.0019345853682708736 -0.00018424622799429358 0.048499998333762874" rpy="0.0 4.722979357162093e-94 0.0"/>
            <mass value="20.286776465465472"/>
            <inertia ixx="0.037187106106497225" iyy="0.14633477738251344" izz="0.1517088368611823" ixy="-0.0003996956972720511" iyz="4.618527782440651e-14" ixz="-3.4772185131259903e-13"/>
        </inertial>
        <visual name="base-plate-left_visual">
            <origin xyz="1.5762219263137923e-09 -1.8000000001525343 -1.6662374946463389e-09" rpy="-1.5707963267948963 5.703770789011712e-15 -9.05742494894392e-16"/>
            <geometry>
                <mesh filename="package://vehicle_arm_sim/meshes/base-plate-left.stl" scale="0.001 0.001 0.001"/>
            </geometry>
        </visual>
        <collision name="base-plate-left_collision">
            <origin xyz="1.5762219263137923e-09 -1.8000000001525343 -1.6662374946463389e-09" rpy="-1.5707963267948963 5.703770789011712e-15 -9.05742494894392e-16"/>
            <geometry>
                <mesh filename="package://vehicle_arm_sim/meshes/base-plate-left.stl" scale="0.001 0.001 0.001"/>
            </geometry>
        </collision>
    </link>
    <link name="right-wheel">
        <inertial>
            <origin xyz="0.08976609726381397 2.4926996962761906e-05 -2.8554460971186304e-06" rpy="0.0 -0.0 0.0"/>
            <mass value="17.643706"/>
            <inertia ixx="0.8667565646974431" iyy="0.4577950260034438" izz="0.45785176901554436" ixy="-1.9217930463000243e-05" iyz="-3.2350953147464168e-06" ixz="-2.6477357955023706e-06"/>
        </inertial>
        <visual name="right-wheel_visual">
            <origin xyz="0.089806 0 0" rpy="0 0 0"/>
            <geometry>
                <mesh filename="package://vehicle_arm_sim/meshes/right-wheel.stl" scale="0.001 0.001 0.001"/>
            </geometry>
            <material name="right-wheel_material">
                <color rgba="0.0863 0.0745 0.0745 1.0"/>
            </material>
        </visual>
        <collision name="right-wheel_collision">
            <origin xyz="0.08980600292939343 -1.8156377734612762e-09 1.1196021887371898e-12" rpy="8.673617379882857e-17 -3.897623472656189e-15 3.671090234079189e-15"/>
            <geometry>
                <mesh filename="package://vehicle_arm_sim/meshes/right-wheel.stl" scale="0.001 0.001 0.001"/>
            </geometry>
            <surface>
                <friction>
                    <ode>
                        <mu>1.0</mu>
                        <mu2>1.0</mu2>
                    </ode>
                </friction>
            </surface>
        </collision>
    </link>
    <link name="axial-right">
        <inertial>
            <origin xyz="-0.026560272848659708 0.008141810073096422 0.18320405571641943" rpy="0.0 -0.0 -2.189528850507527e-47"/>
            <mass value="5.960125317942265"/>
            <inertia ixx="0.19349834660831705" iyy="0.15953275150846125" izz="0.07140362306564982" ixy="0.001216166593576262" iyz="-0.0014155363552106335" ixz="-0.011255587512739636"/>
        </inertial>
        <visual name="axial-right_visual">
            <origin xyz="1.5762225125115492e-09 0.12399999984745406 0.4199999983337595" rpy="-1.5707963267948968 1.155743137021616e-15 -1.5707963267949006"/>
            <geometry>
                <mesh filename="package://vehicle_arm_sim/meshes/axial-right.stl" scale="0.001 0.001 0.001"/>
            </geometry>
        </visual>
        <collision name="axial-right_collision">
            <origin xyz="1.5762225125115492e-09 0.12399999984745406 0.4199999983337595" rpy="-1.5707963267948968 1.155743137021616e-15 -1.5707963267949006"/>
            <geometry>
                <mesh filename="package://vehicle_arm_sim/meshes/axial-right.stl" scale="0.001 0.001 0.001"/>
            </geometry>
        </collision>
    </link>
    <link name="axial-left">
        <inertial>
            <origin xyz="-0.02656027284865676 -0.00814181007308335 -0.18243738480234142" rpy="0.0 -0.0 0.0"/>
            <mass value="5.960125317942265"/>
            <inertia ixx="0.19349834660832066" iyy="0.15953275150846302" izz="0.07140362306564718" ixy="-0.0012161665935745969" iyz="-0.0014155363552097455" ixz="0.011255587512739751"/>
        </inertial>
        <visual name="axial-left_visual">
            <origin xyz="1.5762251415196715e-09 -0.12399999984744099 -0.41923332741968167" rpy="1.5707963267948966 -4.216670939182494e-16 1.5707963267948974"/>
            <geometry>
                <mesh filename="package://vehicle_arm_sim/meshes/axial-left.stl" scale="0.001 0.001 0.001"/>
            </geometry>
        </visual>
        <collision name="axial-left_collision">
            <origin xyz="1.5762251415196715e-09 -0.12399999984744099 -0.41923332741968167" rpy="1.5707963267948966 -4.216670939182494e-16 1.5707963267948974"/>
            <geometry>
                <mesh filename="package://vehicle_arm_sim/meshes/axial-left.stl" scale="0.001 0.001 0.001"/>
            </geometry>
        </collision>
    </link>
    <link name="left-wheel">
        <inertial>
            <origin xyz="0.08976609726380005 2.4926082885201596e-05 -2.855446092233649e-06" rpy="-3.323448711015614e-63 -0.0 0.0"/>
            <mass value="17.643706"/>
            <inertia ixx="0.86675656469744" iyy="0.4577950260034491" izz="0.4578517690155408" ixy="-1.9217930464776604e-05" iyz="-3.2350953143023276e-06" ixz="-2.647735797722817e-06"/>
        </inertial>
        <visual name="left-wheel_visual">
            <origin xyz="0.089806 0 0" rpy="0 0 0"/>
            <geometry><mesh filename="package://vehicle_arm_sim/meshes/left-wheel.stl" scale="0.001 0.001 0.001"/></geometry>
            <material name="left-wheel_material">
                <color rgba="0.0314 0.0275 0.0275 1.0"/>
            </material>
        </visual>
        <collision name="left-wheel_collision">
            <origin xyz="0.0898060029293795 -2.72971533377131e-09 1.1244694064771465e-12" rpy="-5.693600210639377e-16 -1.0824674490095377e-15 7.460184898525892e-15"/>
            <geometry><mesh filename="package://vehicle_arm_sim/meshes/left-wheel.stl" scale="0.001 0.001 0.001"/></geometry>
            <surface>
                <friction>
                    <ode>
                        <mu>1.0</mu>
                        <mu2>1.0</mu2>
                    </ode>
                </friction>
            </surface>
        </collision>
    </link>
    <joint name="axial-front_Revolute-10" type="continuous">
        <origin xyz="4.806000000002087e-05 -0.00799999999999999 -0.3992317399999999" rpy="-1.5707963267948966 -4.8862532784603164e-32 -1.5707963267948966"/>
        <parent link="axial-front"/>
        <child link="front-wheel"/>
        <axis xyz="-1.0 -4.974508036802331e-32 -0.0"/>
        <dynamics damping="0.5" friction="0.1"/>
        <limit effort="500" velocity="20.0"/>
    </joint>
    <joint name="base-v1_to_origin" type="fixed">
        <origin xyz="0.65 0.0 0.9" rpy="-1.5707963267948966 0.0 0.0"/>
        <parent link="base-v1"/>
        <child link="origin"/>
    </joint>
    <joint name="base-v1_Rigid-11" type="fixed">
        <origin xyz="1.3 0 0.9" rpy="-1.570796 0 0"/>
        <parent link="base-v1"/>
        <child link="base-plate-front"/>
    </joint>
    <joint name="base-v1_Rigid-12" type="fixed">
        <origin xyz="-0.002597 0 0" rpy="-1.570796 0 0"/>
        <parent link="base-v1"/>
        <child link="base-plate-right"/>
    </joint>
    <joint name="base-v1_Rigid-13" type="fixed">
        <origin xyz="-1.5762245908490514e-09 -1.6662371393749709e-09 1.8000000001525605" rpy="1.570796326794897 -9.057424948943961e-16 -2.0816681711721774e-16"/>
        <parent link="base-v1"/>
        <child link="base-plate-left"/>
    </joint>
    <joint name="base-plate-front_Revolute-14" type="revolute">
        <origin xyz="0.105 0.01 -0.09700000000000003" rpy="2.3948350467888256e-63 2.237605975518999e-31 0.0"/>
        <parent link="base-plate-front"/>
        <child link="axial-front"/>
        <axis xyz="-2.3590385388993773e-31 0.0 1.0"/>
        <limit lower="-1.570796" upper="1.570796" effort="100" velocity="2.0"/>
        <dynamics damping="1.0" friction="0.5"/>
    </joint>
    <joint name="base-plate-right_Revolute-18" type="revolute">
        <origin xyz="-0.10500000000000002 -0.01 -0.09699999999999996" rpy="3.141592653589793 -7.18779982929554e-32 2.189528850507527e-47"/>
        <parent link="base-plate-right"/>
        <child link="axial-right"/>
        <axis xyz="-5.973474195491757e-32 0.0 0.9999999999999999"/>
        <limit lower="-1.570796" upper="1.570796" effort="100" velocity="2.0"/>
        <dynamics damping="1.0" friction="0.5"/>
    </joint>
    <joint name="axial-right_Revolute-19" type="continuous">
        <origin xyz="4.80600000000031e-05 -0.09219303999999993 0.3999984099999999" rpy="1.5707963267948966 -1.4612587475429843e-32 1.5707963267948966"/>
        <parent link="axial-right"/>
        <child link="right-wheel"/>
        <axis xyz="-1.0 1.1276818820434178e-31 -7.888609052210118e-31"/>
        <dynamics damping="0.5" friction="0.1"/>
        <limit effort="500" velocity="20.0"/>
    </joint>
    <joint name="base-plate-left_Revolute-20" type="revolute">
        <origin xyz="-0.10500000000000002 0.01 0.09700000000000003" rpy="-3.141592653589793 -2.9112058178301707e-31 1.9721522630525295e-31"/>
        <parent link="base-plate-left"/>
        <child link="axial-left"/>
        <axis xyz="-3.032638381210549e-31 0.0 1.0"/>
        <limit lower="-1.570796" upper="1.570796" effort="100" velocity="2.0"/>
        <dynamics damping="1.0" friction="0.5"/>
    </joint>
    <joint name="axial-left_Revolute-21" type="continuous">
        <origin xyz="4.80600000000031e-05 0.09219303999999993 -0.3992317399999999" rpy="-1.5707963267948966 -1.812345601166459e-34 -1.5707963267948966"/>
        <parent link="axial-left"/>
        <child link="left-wheel"/>
        <axis xyz="-1.0000000000000002 3.370377402677343e-32 9.860761315262648e-32"/>
        <dynamics damping="0.5" friction="0.1"/>
        <limit effort="500" velocity="20.0"/>
    </joint>
    <link name="imu_link">
        <inertial>
            <origin xyz="0 0 0" rpy="0 0 0"/>
            <mass value="0.001"/>
            <inertia ixx="0.0001" iyy="0.0001" izz="0.0001" ixy="0" iyz="0" ixz="0"/>
        </inertial>
    </link>
    <joint name="imu_joint" type="fixed">
        <origin xyz="0.65 0.0 0.9" rpy="-1.5707963267948966 0.0 0.0"/>
        <parent link="base-v1"/>
        <child link="imu_link"/>
    </joint>
    <gazebo reference="imu_link">
        <sensor name="imu_sensor" type="imu">
            <always_on>true</always_on>
            <update_rate>100</update_rate>
            <topic>imu</topic>
            <imu>
                <angular_velocity>
                    <x>
                        <noise type="none"/>
                    </x>
                    <y>
                        <noise type="none"/>
                    </y>
                    <z>
                        <noise type="none"/>
                    </z>
                </angular_velocity>
                <linear_acceleration>
                    <x>
                        <noise type="none"/>
                    </x>
                    <y>
                        <noise type="none"/>
                    </y>
                    <z>
                        <noise type="none"/>
                    </z>
                </linear_acceleration>
            </imu>
        </sensor>
    </gazebo>
    <link name="navsat_link">
        <inertial>
            <origin xyz="0 0 0" rpy="0 0 0"/>
            <mass value="0.001"/>
            <inertia ixx="0.0001" iyy="0.0001" izz="0.0001" ixy="0" iyz="0" ixz="0"/>
        </inertial>
    </link>
    <joint name="navsat_joint" type="fixed">
        <origin xyz="0.65 0.0 1.2" rpy="-1.5707963267948966 0.0 0.0"/>
        <parent link="base-v1"/>
        <child link="navsat_link"/>
    </joint>
    <gazebo reference="navsat_link">
        <sensor name="navsat_sensor" type="navsat">
            <always_on>true</always_on>
            <update_rate>10</update_rate>
            <topic>navsat</topic>
        </sensor>
    </gazebo>
    <link name="camera_link">
        <inertial>
            <origin xyz="0 0 0" rpy="0 0 0"/>
            <mass value="0.001"/>
            <inertia ixx="0.0001" iyy="0.0001" izz="0.0001" ixy="0" iyz="0" ixz="0"/>
        </inertial>
    </link>
    <link name="camera_optical_link">
        <inertial>
            <origin xyz="0 0 0" rpy="0 0 0"/>
            <mass value="0.001"/>
            <inertia ixx="0.0001" iyy="0.0001" izz="0.0001" ixy="0" iyz="0" ixz="0"/>
        </inertial>
    </link>
    <joint name="camera_joint" type="fixed">
        <origin xyz="0.016845 0.100461 -0.077129" rpy="1.5708 0.785398 0"/>
        <parent link="arm_yanthra_link"/>
        <child link="camera_link"/>
    </joint>
    <joint name="camera_optical_joint" type="fixed">
        <origin xyz="0 0 0" rpy="-1.5707963267948966 0.0 -1.5707963267948966"/>
        <parent link="camera_link"/>
        <child link="camera_optical_link"/>
    </joint>
    <gazebo reference="camera_link">
        <sensor name="camera_sensor" type="camera">
            <always_on>true</always_on>
            <update_rate>10</update_rate>
            <visualize>true</visualize>
            <topic>front_camera</topic>
            <camera>
                <horizontal_fov>1.2740903539558606</horizontal_fov>
                <image>
                    <width>640</width>
                    <height>480</height>
                    <format>R8G8B8</format>
                </image>
                <clip>
                    <near>0.1</near>
                    <far>100</far>
                </clip>
            </camera>
        </sensor>
    </gazebo>
    <link name="arm_link2">
        <inertial>
            <origin xyz="0.0023258 0.39197 0.0012124" rpy="0 0 0"/>
            <mass value="7.2824"/>
            <inertia ixx="0.56505" ixy="-0.0011051" ixz="0.00023875" iyy="0.0071252" iyz="-0.00046822" izz="0.56327"/>
        </inertial>
        <visual>
            <origin xyz="0 0 -0.445" rpy="0 0 0"/>
            <geometry><mesh filename="package://vehicle_arm_sim/meshes/link2.STL" scale="1 1 1"/></geometry>
            <material name="arm_link2_material_1">
                <color rgba="0.0000 0.0196 0.6000 1.0"/>
            </material>
        </visual>
        <collision>
            <origin xyz="0 0 0" rpy="0 0 0"/>
            <geometry><mesh filename="package://vehicle_arm_sim/meshes/link2.STL" scale="1 1 1"/></geometry>
        </collision>
    </link>
    <link name="arm_link4">
        <inertial>
            <origin xyz="-0.044144 0.0378 -0.072925" rpy="0 0 0"/>
            <mass value="0.86357"/>
            <inertia ixx="0.0063398" ixy="0.00091722" ixz="-0.0017328" iyy="0.0061419" iyz="0.0015638" izz="0.0031822"/>
        </inertial>
        <visual>
            <origin xyz="0.008 -0.334 -0.459" rpy="0 0 0"/>
            <geometry>
                <mesh filename="package://vehicle_arm_sim/meshes/link4.STL"/>
            </geometry>
            <material name="arm_link4_material_2">
                <color rgba="0.292156862745098 0.119607843137255 0.933333333333333 1"/>
            </material>
        </visual>
        <collision>
            <origin xyz="0 0 0" rpy="0 0 0"/>
            <geometry>
                <mesh filename="package://vehicle_arm_sim/meshes/link4.STL"/>
            </geometry>
        </collision>
    </link>
    <link name="arm_link3">
        <inertial>
            <origin xyz="-0.033163 -0.04027 -0.0050659" rpy="0 0 0"/>
            <mass value="1.4316"/>
            <inertia ixx="0.0037572" ixy="-0.00082268" ixz="-0.0011479" iyy="0.043868" iyz="-0.00017008" izz="0.044751"/>
        </inertial>
        <visual>
            <origin xyz="0.069 -0.378 -0.330" rpy="0 0 0"/>
            <geometry>
                <mesh filename="package://vehicle_arm_sim/meshes/link3.STL"/>
            </geometry>
            <material name="arm_link3_material_3">
                <color rgba="0.592156862745098 0.79607843137255 0.233333333333333 1"/>
            </material>
        </visual>
        <collision>
            <origin xyz="0 0 0" rpy="0 0 0"/>
            <geometry>
                <mesh filename="package://vehicle_arm_sim/meshes/link3.STL"/>
            </geometry>
        </collision>
    </link>
    <link name="arm_yanthra_link">
        <inertial>
            <origin xyz="0 0 0" rpy="0 0 0"/>
            <mass value="0.01"/>
            <inertia ixx="0.0001" ixy="0" ixz="0" iyy="0.0001" iyz="0" izz="0.0001"/>
        </inertial>
        <visual>
            <geometry>
                <box size="0.001 0.001 0.001"/>
            </geometry>
        </visual>
        <collision>
            <origin xyz="0 0 0" rpy="0 0 0"/>
            <geometry>
                <box size="0.001 0.001 0.001"/>
            </geometry>
        </collision>
    </link>
    <link name="arm_link5_origin">
        <inertial>
            <origin xyz="0 0 0" rpy="0 0 0"/>
            <mass value="0.01"/>
            <inertia ixx="0.0001" ixy="0" ixz="0" iyy="0.0001" iyz="0" izz="0.0001"/>
        </inertial>
        <visual>
            <geometry>
                <box size="0.001 0.001 0.001"/>
            </geometry>
        </visual>
        <collision>
            <origin xyz="0 0 0" rpy="0 0 0"/>
            <geometry>
                <box size="0.001 0.001 0.001"/>
            </geometry>
        </collision>
    </link>
    <link name="arm_link5">
        <inertial>
            <origin xyz="-0.24702 0.0038414 0.0022102" rpy="0 0 0"/>
            <mass value="0.50477"/>
            <inertia ixx="0.00073373" ixy="0.00051748" ixz="-0.00013446" iyy="0.014642" iyz="4.7355E-06" izz="0.014712"/>
        </inertial>
        <visual>
            <origin xyz="-0.209 -0.300 -0.329" rpy="0 0 0"/>
            <geometry>
                <mesh filename="package://vehicle_arm_sim/meshes/link5.STL"/>
            </geometry>
            <material name="arm_link5_material_4">
                <color rgba="0.25 0.28 0.3 1"/>
            </material>
        </visual>
        <collision>
            <origin xyz="0 0 0" rpy="0 0 0"/>
            <geometry>
                <mesh filename="package://vehicle_arm_sim/meshes/link5.STL"/>
            </geometry>
        </collision>
    </link>
    <link name="arm_ee_link">
        <inertial>
            <origin xyz="0 0 0" rpy="0 0 0"/>
            <mass value="0.01"/>
            <inertia ixx="0.0001" ixy="0" ixz="0" iyy="0.0001" iyz="0" izz="0.0001"/>
        </inertial>
        <visual>
            <geometry>
                <box size="0.001 0.001 0.001"/>
            </geometry>
        </visual>
        <collision>
            <origin xyz="0 0 0" rpy="0 0 0"/>
            <geometry>
                <box size="0.001 0.001 0.001"/>
            </geometry>
        </collision>
    </link>
    <joint name="arm_joint4" type="prismatic">
        <origin xyz="0 0.33411 0" rpy="0 0 0"/>
        <parent link="arm_link2"/>
        <child link="arm_link4"/>
        <axis xyz="0 1 0"/>
        <limit lower="-0.250" upper="0.350" effort="100" velocity="0.5"/>
    </joint>
    <joint name="arm_joint3" type="revolute">
        <origin xyz="-0.069574 0.009556 -0.12761" rpy="0 0.006395 0"/>
        <parent link="arm_link4"/>
        <child link="arm_link3"/>
        <axis xyz="0 -1 0"/>
        <limit lower="-0.9" upper="0.0" effort="100" velocity="1.0"/>
    </joint>
    <joint name="arm_yantra_joint" type="fixed">
        <origin xyz="0 -0.082 0" rpy="0 0 0"/>
        <parent link="arm_link3"/>
        <child link="arm_yanthra_link"/>
    </joint>
    <joint name="arm_link5_origin_joint" type="fixed">
        <origin xyz="0 0 0" rpy="0 0 0"/>
        <parent link="arm_yanthra_link"/>
        <child link="arm_link5_origin"/>
    </joint>
    <joint name="arm_joint5" type="prismatic">
        <origin xyz="0.278326 0.012934 -0.000824" rpy="0 0 0"/>
        <parent link="arm_link5_origin"/>
        <child link="arm_link5"/>
        <axis xyz="1 0 0"/>
        <limit lower="0" upper="0.450" effort="100" velocity="0.5"/>
    </joint>
    <joint name="arm_ee_joint" type="fixed">
        <origin xyz="0 0 0" rpy="0 0 0"/>
        <parent link="arm_link5"/>
        <child link="arm_ee_link"/>
    </joint>
    <gazebo>
        <plugin filename="libgz-sim-joint-position-controller-system.so" name="gz::sim::systems::JointPositionController">
            <joint_name>arm_joint3</joint_name>
            <topic>joint3_cmd</topic>
            <p_gain>800</p_gain>
            <i_gain>10.0</i_gain>
            <d_gain>80</d_gain>
            <i_max>100</i_max>
            <i_min>-100</i_min>
            <cmd_max>500</cmd_max>
            <cmd_min>-500</cmd_min>
            <cmd_offset>0.0</cmd_offset>
        </plugin>
    </gazebo>
    <gazebo>
        <plugin filename="libgz-sim-joint-position-controller-system.so" name="gz::sim::systems::JointPositionController">
            <joint_name>arm_joint4</joint_name>
            <topic>joint4_cmd</topic>
            <p_gain>500</p_gain>
            <i_gain>5.0</i_gain>
            <d_gain>50</d_gain>
            <i_max>80</i_max>
            <i_min>-80</i_min>
            <cmd_max>500</cmd_max>
            <cmd_min>-500</cmd_min>
            <cmd_offset>0.0</cmd_offset>
        </plugin>
    </gazebo>
    <gazebo>
        <plugin filename="libgz-sim-joint-position-controller-system.so" name="gz::sim::systems::JointPositionController">
            <joint_name>arm_joint5</joint_name>
            <topic>joint5_cmd</topic>
            <p_gain>500</p_gain>
            <i_gain>5.0</i_gain>
            <d_gain>50</d_gain>
            <i_max>80</i_max>
            <i_min>-80</i_min>
            <cmd_max>500</cmd_max>
            <cmd_min>-500</cmd_min>
            <cmd_offset>0.0</cmd_offset>
        </plugin>
    </gazebo>
    <gazebo>
        <plugin filename="libgz-sim-joint-state-publisher-system.so" name="gz::sim::systems::JointStatePublisher">
            <joint_name>arm_joint3</joint_name>
            <joint_name>arm_joint4</joint_name>
            <joint_name>arm_joint5</joint_name>
        </plugin>
    </gazebo>
    <gazebo reference="arm_link2">
        <material>Gazebo/Blue</material>
    <visual><material><ambient>0.0000 0.0196 0.6000 1</ambient><diffuse>0.0000 0.0196 0.6000 1</diffuse></material></visual></gazebo>
    <gazebo reference="arm_link3">
        <material>Gazebo/Green</material>
    </gazebo>
    <gazebo reference="arm_link4">
        <material>Gazebo/Purple</material>
    </gazebo>
    <gazebo reference="arm_link5">
        <material>Gazebo/White</material>
    </gazebo>
    <joint name="base-v1_to_arm_link2_joint" type="fixed">
        <parent link="base-v1"/>
        <child link="arm_link2"/>
        <origin xyz="0.338848 0.394908 0" rpy="-1.521774 -1.550976 -0.049013"/>
    </joint>
    <link name="arm_top_Component2">
        <inertial>
            <origin xyz="-0.24465088161211476 0.010585973180471987 0.11091969064068309" rpy="0.0 -0.0 -4.494409300504508e-94"/>
            <mass value="2.732553"/>
            <inertia ixx="0.019945673059615317" iyy="0.3093216702465301" izz="0.2907100794669303" ixy="-0.0006508067571328429" iyz="-0.002854246151097408" ixz="-0.0036114894797260747"/>
        </inertial>
        <visual name="Component2_visual">
            <origin xyz="0.400815 -0.003195 0.178301" rpy="0 0 1.570796"/>
            <geometry>
                <mesh filename="package://vehicle_arm_sim/meshes/Component2.stl" scale="0.001 0.001 0.001"/>
            </geometry>
            <material name="arm_top_Component2_material">
                <color rgba="0.7020 0.7020 0.7020 1.0"/>
            </material>
        </visual>
        <collision name="Component2_collision">
            <origin xyz="0.400815 -0.0031948999999999988 0.17830079" rpy="1.8488927466117464e-31 -3.646298014371762e-62 1.5707963267948966"/>
            <geometry>
                <mesh filename="package://vehicle_arm_sim/meshes/Component2.stl" scale="0.001 0.001 0.001"/>
            </geometry>
        </collision>
    </link>
    <link name="arm_top_colle.box-holding-v1">
        <inertial>
            <origin xyz="0.21514017506062483 -0.015999999999999615 -0.013681869298376129" rpy="0.0 0.0 0.0"/>
            <mass value="0.342606"/>
            <inertia ixx="0.00043003932571770157" iyy="0.011122906290419732" izz="0.01075133830821507" ixy="5.613330715348987e-17" iyz="-1.0905687748614085e-16" ixz="-0.001077144265120561"/>
        </inertial>
        <visual name="colle.box-holding-v1_visual">
            <origin xyz="0 0 0" rpy="0 0 0"/>
            <geometry>
                <mesh filename="package://vehicle_arm_sim/meshes/colle.box-holding-v1.stl" scale="0.001 0.001 0.001"/>
            </geometry>
            <material name="arm_top_colle.box-holding-v1_material">
                <color rgba="0.8431 0.5608 0.0784 1.0"/>
            </material>
        </visual>
        <collision name="colle.box-holding-v1_collision">
            <origin xyz="0.0 0.0 0.0" rpy="0.0 0.0 0.0"/>
            <geometry>
                <mesh filename="package://vehicle_arm_sim/meshes/colle.box-holding-v1.stl" scale="0.001 0.001 0.001"/>
            </geometry>
        </collision>
    </link>
    <link name="arm_top_colle.box-holding-v1_2">
        <inertial>
            <origin xyz="0.32628701238474833 -1.1652900866465644e-14 0.015681866892208914" rpy="0.0 -0.0 0.0"/>
            <mass value="0.342606"/>
            <inertia ixx="0.00043003932571770076" iyy="0.011122906290419676" izz="0.010751338308214758" ixy="-3.662363552223758e-17" iyz="9.057648485122138e-17" ixz="-0.0010771442651205756"/>
        </inertial>
        <visual name="colle.box-holding-v1_visual">
            <origin xyz="0.541427 0.016 0.002" rpy="3.141593 0 3.141593"/>
            <geometry><mesh filename="package://vehicle_arm_sim/meshes/colle.box-holding-v1.stl" scale="0.001 0.001 0.001"/></geometry>
            <material name="arm_top_colle.box-holding-v1_2_material">
                <color rgba="0.9020 0.5255 0.0980 1.0"/>
            </material>
        </visual>
        <collision name="colle.box-holding-v1_collision">
            <origin xyz="0.5414271874453744 0.01599999999998829 0.001999997593832927" rpy="3.14159265358979 1.3045120539345528e-15 3.141592653589793"/>
            <geometry><mesh filename="package://vehicle_arm_sim/meshes/colle.box-holding-v1.stl" scale="0.001 0.001 0.001"/></geometry>
        </collision>
    </link>
    <link name="arm_top_collection-box-v1">
        <inertial>
            <origin xyz="-0.046580819250886946 -0.3000000000000152 0.041453016072315683" rpy="-7.006492321624085e-46 -0.0 0.0"/>
            <mass value="2.808761"/>
            <inertia ixx="0.13035730185851852" iyy="0.025524525896721398" izz="0.11899707598580728" ixy="-4.5945544145968535e-16" iyz="1.1696557964289162e-17" ixz="-0.001106377875146882"/>
        </inertial>
        <visual name="collection-box-v1_visual">
            <origin xyz="-0.13617 0 0.150561" rpy="1.570796 -1.47461 0"/>
            <geometry>
                <mesh filename="package://vehicle_arm_sim/meshes/collection-box-v1.stl" scale="0.001 0.001 0.001"/>
            </geometry>
            <material name="arm_top_collection-box-v1_material">
                <color rgba="0.8078 0.5529 0.1098 1.0"/>
            </material>
        </visual>
        <collision name="collection-box-v1_collision">
            <origin xyz="-0.13616983694617538 -1.3358203432289884e-14 0.15056128893417614" rpy="1.570796326794917 -1.4746101983838649 -1.8764486226169754e-14"/>
            <geometry>
                <mesh filename="package://vehicle_arm_sim/meshes/collection-box-v1.stl" scale="0.001 0.001 0.001"/>
            </geometry>
        </collision>
    </link>
    <joint name="arm_top_colle.box-holding-v1_Rigid-1" type="fixed">
        <origin xyz="0.54134 -0.012373 0.001869" rpy="-1.47461 0 -1.570796"/>
        <parent link="arm_top_colle.box-holding-v1"/>
        <child link="arm_top_Component2"/>
    </joint>
    <joint name="arm_top_Component2_Rigid-2" type="fixed">
        <origin xyz="-0.535715 -0.006695 -0.069385" rpy="3.141593 1.47461 -1.570796"/>
        <parent link="arm_top_Component2"/>
        <child link="arm_top_colle.box-holding-v1_2"/>
    </joint>
    <joint name="arm_top_colle.box-holding-v1_Rigid-3" type="fixed">
        <origin xyz="0.539427 0.016 0.072255" rpy="0 -0.096186 0"/>
        <parent link="arm_top_colle.box-holding-v1_2"/>
        <child link="arm_top_collection-box-v1"/>
    </joint>
    <gazebo reference="arm_top_colle.box-holding-v1">
        <visual>
            <material>
                <ambient>0.8431 0.5608 0.0784 1</ambient>
                <diffuse>0.8431 0.5608 0.0784 1</diffuse>
            </material>
        </visual>
    </gazebo>
    <gazebo reference="arm_top_Component2">
        <visual>
            <material>
                <ambient>0.7020 0.7020 0.7020 1</ambient>
                <diffuse>0.7020 0.7020 0.7020 1</diffuse>
            </material>
        </visual>
    </gazebo>
    <link name="jointt">
        <visual>
            <origin xyz="0 0 0" rpy="0 0 0"/>
            <geometry>
                <sphere radius="0.025"/>
            </geometry>
            <material name="jointt_material">
                <color rgba="0.3569 0.6078 0.8353 1.0"/>
            </material>
        </visual>
        <collision>
            <geometry>
                <sphere radius="0.05"/>
            </geometry>
        </collision>
        <inertial>
            <mass value="1"/>
            <inertia ixx="0.001" ixy="0" ixz="0" iyy="0.001" iyz="0" izz="0.001"/>
        </inertial>
    </link>
    <joint name="arm_top_colle.box-holding-v1_to_jointt_joint" type="fixed">
        <parent link="arm_top_colle.box-holding-v1"/>
        <child link="jointt"/>
        <origin xyz="0.715118 -0.419133 0.000544" rpy="0 0 0"/>
    </joint>
    <gazebo reference="jointt">
        <visual>
            <material>
                <ambient>0.3569 0.6078 0.8353 1</ambient>
                <diffuse>0.3569 0.6078 0.8353 1</diffuse>
            </material>
        </visual>
    </gazebo>
    <gazebo reference="jointt2">
        <visual>
            <material>
                <ambient>0.3569 0.6078 0.8353 1</ambient>
                <diffuse>0.3569 0.6078 0.8353 1</diffuse>
            </material>
        </visual>
    </gazebo>
    <link name="jointt2">
        <visual>
            <origin xyz="0 0 0" rpy="0 0 0"/>
            <geometry>
                <sphere radius="0.025"/>
            </geometry>
            <material name="jointt2_material">
                <color rgba="0.3569 0.6078 0.8353 1.0"/>
            </material>
        </visual>
        <collision>
            <geometry>
                <sphere radius="0.05"/>
            </geometry>
        </collision>
        <inertial>
            <mass value="1"/>
            <inertia ixx="0.001" ixy="0" ixz="0" iyy="0.001" iyz="0" izz="0.001"/>
        </inertial>
    </link>
    <joint name="arm_top_colle.box-holding-v1_2_to_jointt2_joint" type="fixed">
        <parent link="arm_top_colle.box-holding-v1_2"/>
        <child link="jointt2"/>
        <origin xyz="-0.238891 0.328853 0.004636" rpy="0 0 0"/>
    </joint>
    <joint name="base-v1_to_arm_top_colle.box-holding-v1_joint" type="fixed">
        <parent link="base-v1"/>
        <child link="arm_top_colle.box-holding-v1"/>
        <origin xyz="0.872666 -0.201367 0" rpy="0 0 1.581046"/>
    </joint>
    <gazebo reference="arm_top_colle.box-holding-v1_2">
        <visual>
            <material>
                <ambient>0.9020 0.5255 0.0980 1</ambient>
                <diffuse>0.9020 0.5255 0.0980 1</diffuse>
            </material>
        </visual>
    </gazebo>
    <gazebo reference="arm_top_collection-box-v1">
        <visual>
            <material>
                <ambient>0.8078 0.5529 0.1098 1</ambient>
                <diffuse>0.8078 0.5529 0.1098 1</diffuse>
            </material>
        </visual>
    </gazebo>
    <link name="arm_link2_copy">
        <inertial>
            <origin xyz="0.0023258 0.39197 0.0012124" rpy="0 0 0"/>
            <mass value="7.2824"/>
            <inertia ixx="0.56505" ixy="-0.0011051" ixz="0.00023875" iyy="0.0071252" iyz="-0.00046822" izz="0.56327"/>
        </inertial>
        <visual>
            <origin xyz="0 0 -0.445" rpy="0 0 0"/>
            <geometry><mesh filename="package://vehicle_arm_sim/meshes/link2.STL" scale="1 1 1"/></geometry>
            <material name="arm_link2_material_1">
                <color rgba="0.0000 0.0196 0.6000 1.0"/>
            </material>
        </visual>
        <collision>
            <origin xyz="0 0 0" rpy="0 0 0"/>
            <geometry><mesh filename="package://vehicle_arm_sim/meshes/link2.STL" scale="1 1 1"/></geometry>
        </collision>
    </link>
    <link name="arm_link4_copy">
        <inertial>
            <origin xyz="-0.044144 0.0378 -0.072925" rpy="0 0 0"/>
            <mass value="0.86357"/>
            <inertia ixx="0.0063398" ixy="0.00091722" ixz="-0.0017328" iyy="0.0061419" iyz="0.0015638" izz="0.0031822"/>
        </inertial>
        <visual>
            <origin xyz="0.008 -0.334 -0.459" rpy="0 0 0"/>
            <geometry>
                <mesh filename="package://vehicle_arm_sim/meshes/link4.STL"/>
            </geometry>
            <material name="arm_link4_material_2">
                <color rgba="0.292156862745098 0.119607843137255 0.933333333333333 1"/>
            </material>
        </visual>
        <collision>
            <origin xyz="0 0 0" rpy="0 0 0"/>
            <geometry>
                <mesh filename="package://vehicle_arm_sim/meshes/link4.STL"/>
            </geometry>
        </collision>
    </link>
    <link name="arm_link3_copy">
        <inertial>
            <origin xyz="-0.033163 -0.04027 -0.0050659" rpy="0 0 0"/>
            <mass value="1.4316"/>
            <inertia ixx="0.0037572" ixy="-0.00082268" ixz="-0.0011479" iyy="0.043868" iyz="-0.00017008" izz="0.044751"/>
        </inertial>
        <visual>
            <origin xyz="0.069 -0.378 -0.330" rpy="0 0 0"/>
            <geometry>
                <mesh filename="package://vehicle_arm_sim/meshes/link3.STL"/>
            </geometry>
            <material name="arm_link3_material_3">
                <color rgba="0.592156862745098 0.79607843137255 0.233333333333333 1"/>
            </material>
        </visual>
        <collision>
            <origin xyz="0 0 0" rpy="0 0 0"/>
            <geometry>
                <mesh filename="package://vehicle_arm_sim/meshes/link3.STL"/>
            </geometry>
        </collision>
    </link>
    <link name="arm_yanthra_link_copy">
        <inertial>
            <origin xyz="0 0 0" rpy="0 0 0"/>
            <mass value="0.01"/>
            <inertia ixx="0.0001" ixy="0" ixz="0" iyy="0.0001" iyz="0" izz="0.0001"/>
        </inertial>
        <visual>
            <geometry>
                <box size="0.001 0.001 0.001"/>
            </geometry>
        </visual>
        <collision>
            <origin xyz="0 0 0" rpy="0 0 0"/>
            <geometry>
                <box size="0.001 0.001 0.001"/>
            </geometry>
        </collision>
    </link>
    <link name="arm_link5_origin_copy">
        <inertial>
            <origin xyz="0 0 0" rpy="0 0 0"/>
            <mass value="0.01"/>
            <inertia ixx="0.0001" ixy="0" ixz="0" iyy="0.0001" iyz="0" izz="0.0001"/>
        </inertial>
        <visual>
            <geometry>  
                <box size="0.001 0.001 0.001"/>
            </geometry>
        </visual>
        <collision>
            <origin xyz="0 0 0" rpy="0 0 0"/>
            <geometry>
                <box size="0.001 0.001 0.001"/>
            </geometry>
        </collision>
    </link>
    <link name="arm_link5_copy">
        <inertial>
            <origin xyz="-0.24702 0.0038414 0.0022102" rpy="0 0 0"/>
            <mass value="0.50477"/>
            <inertia ixx="0.00073373" ixy="0.00051748" ixz="-0.00013446" iyy="0.014642" iyz="4.7355E-06" izz="0.014712"/>
        </inertial>
        <visual>
            <origin xyz="-0.209 -0.300 -0.329" rpy="0 0 0"/>
            <geometry>
                <mesh filename="package://vehicle_arm_sim/meshes/link5.STL"/>
            </geometry>
            <material name="arm_link5_material_4">
                <color rgba="0.25 0.28 0.3 1"/>
            </material>
        </visual>
        <collision>
            <origin xyz="0 0 0" rpy="0 0 0"/>
            <geometry>
                <mesh filename="package://vehicle_arm_sim/meshes/link5.STL"/>
            </geometry>
        </collision>
    </link>
    <link name="arm_ee_link_copy">
        <inertial>
            <origin xyz="0 0 0" rpy="0 0 0"/>
            <mass value="0.01"/>
            <inertia ixx="0.0001" ixy="0" ixz="0" iyy="0.0001" iyz="0" izz="0.0001"/>
        </inertial>
        <visual>
            <geometry>
                <box size="0.001 0.001 0.001"/>
            </geometry>
        </visual>
        <collision>
            <origin xyz="0 0 0" rpy="0 0 0"/>
            <geometry>
                <box size="0.001 0.001 0.001"/>
            </geometry>
        </collision>
    </link>
    <joint name="base-v1_to_arm_link2_joint_copy" type="fixed">
        <parent link="base-v1"/>
        <child link="arm_link2_copy"/>
        <origin xyz="0.962961 0.40477 1.806531" rpy="-1.675779 1.561533 -0.087054"/>
    </joint>
    <joint name="arm_joint4_copy" type="prismatic">
        <origin xyz="0 0.33411 0" rpy="0 0 0"/>
        <parent link="arm_link2_copy"/>
        <child link="arm_link4_copy"/>
        <axis xyz="0 1 0"/>
        <limit lower="-0.250" upper="0.350" effort="100" velocity="0.5"/>
    </joint>
    <joint name="arm_joint3_copy" type="revolute">
        <origin xyz="-0.069574 0.009556 -0.12761" rpy="0 0.006395 0"/>
        <parent link="arm_link4_copy"/>
        <child link="arm_link3_copy"/>
        <axis xyz="0 -1 0"/>
        <limit lower="-0.9" upper="0.0" effort="100" velocity="1.0"/>
    </joint>
    <joint name="arm_yantra_joint_copy" type="fixed">
        <origin xyz="0 -0.082 0" rpy="0 0 0"/>
        <parent link="arm_link3_copy"/>
        <child link="arm_yanthra_link_copy"/>
    </joint>
    <joint name="arm_link5_origin_joint_copy" type="fixed">
        <origin xyz="0 0 0" rpy="0 0 0"/>
        <parent link="arm_yanthra_link_copy"/>
        <child link="arm_link5_origin_copy"/>
    </joint>
    <joint name="arm_joint5_copy" type="prismatic">
        <origin xyz="0.278326 0.012934 -0.000824" rpy="0 0 0"/>
        <parent link="arm_link5_origin_copy"/>
        <child link="arm_link5_copy"/>
        <axis xyz="1 0 0"/>
        <limit lower="0" upper="0.450" effort="100" velocity="0.5"/>
    </joint>
    <joint name="arm_ee_joint_copy" type="fixed">
        <origin xyz="0 0 0" rpy="0 0 0"/>
        <parent link="arm_link5_copy"/>
        <child link="arm_ee_link_copy"/>
    </joint>
    <link name="arm_top_Component2_2">
        <inertial>
            <origin xyz="-0.24465088161211476 0.010585973180471987 0.11091969064068309" rpy="0.0 -0.0 -4.494409300504508e-94"/>
            <mass value="2.732553"/>
            <inertia ixx="0.019945673059615317" iyy="0.3093216702465301" izz="0.2907100794669303" ixy="-0.0006508067571328429" iyz="-0.002854246151097408" ixz="-0.0036114894797260747"/>
        </inertial>
        <visual name="Component2_visual">
            <origin xyz="0.400815 -0.003195 0.178301" rpy="0 0 1.570796"/>
            <geometry>
                <mesh filename="package://vehicle_arm_sim/meshes/Component2.stl" scale="0.001 0.001 0.001"/>
            </geometry>
            <material name="arm_top_Component2_2_material">
                <color rgba="0.4784 0.4784 0.4784 1.0"/>
            </material>
        </visual>
        <collision name="Component2_collision">
            <origin xyz="0.400815 -0.0031948999999999988 0.17830079" rpy="1.8488927466117464e-31 -3.646298014371762e-62 1.5707963267948966"/>
            <geometry>
                <mesh filename="package://vehicle_arm_sim/meshes/Component2.stl" scale="0.001 0.001 0.001"/>
            </geometry>
        </collision>
    </link>
    <link name="arm_top_colle.box-holding-v1_3">
        <inertial>
            <origin xyz="0.21514017506062483 -0.015999999999999615 -0.013681869298376129" rpy="0.0 0.0 0.0"/>
            <mass value="0.342606"/>
            <inertia ixx="0.00043003932571770157" iyy="0.011122906290419732" izz="0.01075133830821507" ixy="5.613330715348987e-17" iyz="-1.0905687748614085e-16" ixz="-0.001077144265120561"/>
        </inertial>
        <visual name="colle.box-holding-v1_visual">
            <origin xyz="0 0 0" rpy="0 0 0"/>
            <geometry><mesh filename="package://vehicle_arm_sim/meshes/colle.box-holding-v1.stl" scale="0.001 0.001 0.001"/></geometry>
            <material name="arm_top_colle.box-holding-v1_3_material">
                <color rgba="1.0000 0.6824 0.0000 1.0"/>
            </material>
        </visual>
        <collision name="colle.box-holding-v1_collision">
            <origin xyz="0.0 0.0 0.0" rpy="0.0 0.0 0.0"/>
            <geometry><mesh filename="package://vehicle_arm_sim/meshes/colle.box-holding-v1.stl" scale="0.001 0.001 0.001"/></geometry>
        </collision>
    </link>
    <link name="arm_top_colle.box-holding-v1_4">
        <inertial>
            <origin xyz="0.32628701238474833 -1.1652900866465644e-14 0.015681866892208914" rpy="0.0 -0.0 0.0"/>
            <mass value="0.342606"/>
            <inertia ixx="0.00043003932571770076" iyy="0.011122906290419676" izz="0.010751338308214758" ixy="-3.662363552223758e-17" iyz="9.057648485122138e-17" ixz="-0.0010771442651205756"/>
        </inertial>
        <visual name="colle.box-holding-v1_visual">
            <origin xyz="0.541427 0.016 0.002" rpy="3.141593 0 3.141593"/>
            <geometry><mesh filename="package://vehicle_arm_sim/meshes/colle.box-holding-v1.stl" scale="0.001 0.001 0.001"/></geometry>
            <material name="arm_top_colle.box-holding-v1_4_material">
                <color rgba="0.8431 0.5529 0.0588 1.0"/>
            </material>
        </visual>
        <collision name="colle.box-holding-v1_collision">
            <origin xyz="0.5414271874453744 0.01599999999998829 0.001999997593832927" rpy="3.14159265358979 1.3045120539345528e-15 3.141592653589793"/>
            <geometry><mesh filename="package://vehicle_arm_sim/meshes/colle.box-holding-v1.stl" scale="0.001 0.001 0.001"/></geometry>
        </collision>
    </link>
    <link name="arm_top_collection-box-v1_2">
        <inertial>
            <origin xyz="-0.046580819250886946 -0.3000000000000152 0.041453016072315683" rpy="-7.006492321624085e-46 -0.0 0.0"/>
            <mass value="2.808761"/>
            <inertia ixx="0.13035730185851852" iyy="0.025524525896721398" izz="0.11899707598580728" ixy="-4.5945544145968535e-16" iyz="1.1696557964289162e-17" ixz="-0.001106377875146882"/>
        </inertial>
        <visual name="collection-box-v1_visual">
            <origin xyz="-0.13617 0 0.150561" rpy="1.570796 -1.47461 0"/>
            <geometry>
                <mesh filename="package://vehicle_arm_sim/meshes/collection-box-v1.stl" scale="0.001 0.001 0.001"/>
            </geometry>
            <material name="arm_top_collection-box-v1_2_material">
                <color rgba="0.9529 0.6275 0.0706 1.0"/>
            </material>
        </visual>
        <collision name="collection-box-v1_collision">
            <origin xyz="-0.13616983694617538 -1.3358203432289884e-14 0.15056128893417614" rpy="1.570796326794917 -1.4746101983838649 -1.8764486226169754e-14"/>
            <geometry>
                <mesh filename="package://vehicle_arm_sim/meshes/collection-box-v1.stl" scale="0.001 0.001 0.001"/>
            </geometry>
        </collision>
    </link>
    <joint name="arm_top_colle.box-holding-v1_Rigid-1_2" type="fixed">
        <origin xyz="0.5414271874453719 -0.015999999999988645 0.0019999975938320923" rpy="-1.4746101983838633 2.878308632890911e-15 -1.5707963267948968"/>
        <parent link="arm_top_colle.box-holding-v1_3"/>
        <child link="arm_top_Component2_2"/>
    </joint>
    <joint name="arm_top_Component2_Rigid-2_2" type="fixed">
        <origin xyz="-0.533646 -0.006556 -0.067946" rpy="3.141593 1.47461 -1.570796"/>
        <parent link="arm_top_Component2_2"/>
        <child link="arm_top_colle.box-holding-v1_4"/>
    </joint>
    <joint name="arm_top_colle.box-holding-v1_Rigid-3_2" type="fixed">
        <origin xyz="0.5394271910422146 0.015999999999999945 0.07225528179247218" rpy="1.9021844316519041e-16 -0.0961861284110323 -1.9806605463895765e-15"/>
        <parent link="arm_top_colle.box-holding-v1_4"/>
        <child link="arm_top_collection-box-v1_2"/>
    </joint>
    <joint name="base-v1_to_arm_top_colle.box-holding-v1_3_joint" type="fixed">
        <parent link="base-v1"/>
        <child link="arm_top_colle.box-holding-v1_3"/>
        <origin xyz="0.458996 -0.206653 1.801088" rpy="-3.135919 -0.000113 1.590632"/>
    </joint>
    <gazebo reference="arm_link2_copy">
        <visual>
            <material>
                <ambient>0.0000 0.0196 0.6000 1</ambient>
                <diffuse>0.0000 0.0196 0.6000 1</diffuse>
            </material>
        </visual>
    </gazebo>
    <link name="jointt4">
        <visual>
            <origin xyz="0 0 0" rpy="0 0 0"/>
            <geometry>
                <sphere radius="0.03"/>
            </geometry>
            <material name="jointt4_material">
                <color rgba="0.3569 0.6078 0.8353 1.0"/>
            </material>
        </visual>
        <collision>
            <geometry>
                <sphere radius="0.05"/>
            </geometry>
        </collision>
        <inertial>
            <mass value="1"/>
            <inertia ixx="0.001" ixy="0" ixz="0" iyy="0.001" iyz="0" izz="0.001"/>
        </inertial>
    </link>
    <joint name="arm_top_colle.box-holding-v1_3_to_jointt4_joint" type="fixed">
        <parent link="arm_top_colle.box-holding-v1_3"/>
        <child link="jointt4"/>
        <origin xyz="0.714566 -0.431358 0.005008" rpy="0 0 0"/>
    </joint>
    <gazebo reference="jointt4">
        <visual>
            <material>
                <ambient>0.3569 0.6078 0.8353 1</ambient>
                <diffuse>0.3569 0.6078 0.8353 1</diffuse>
            </material>
        </visual>
    </gazebo>
    <link name="jointt5">
        <visual>
            <origin xyz="0 0 0" rpy="0 0 0"/>
            <geometry>
                <sphere radius="0.03"/>
            </geometry>
            <material name="jointt5_material">
                <color rgba="0.3569 0.6078 0.8353 1.0"/>
            </material>
        </visual>
        <collision>
            <geometry>
                <sphere radius="0.05"/>
            </geometry>
        </collision>
        <inertial>
            <mass value="1"/>
            <inertia ixx="0.001" ixy="0" ixz="0" iyy="0.001" iyz="0" izz="0.001"/>
        </inertial>
    </link>
    <joint name="arm_top_colle.box-holding-v1_4_to_jointt5_joint" type="fixed">
        <parent link="arm_top_colle.box-holding-v1_4"/>
        <child link="jointt5"/>
        <origin xyz="-0.234822 0.329242 0.005276" rpy="0 0 0"/>
    </joint>
    <gazebo reference="jointt5">
        <visual>
            <material>
                <ambient>0.3569 0.6078 0.8353 1</ambient>
                <diffuse>0.3569 0.6078 0.8353 1</diffuse>
            </material>
        </visual>
    </gazebo>
    <gazebo reference="arm_top_colle.box-holding-v1_4">
        <visual>
            <material>
                <ambient>0.8431 0.5529 0.0588 1</ambient>
                <diffuse>0.8431 0.5529 0.0588 1</diffuse>
            </material>
        </visual>
    </gazebo>
    <gazebo reference="arm_top_colle.box-holding-v1_3">
        <visual>
            <material>
                <ambient>1.0000 0.6824 0.0000 1</ambient>
                <diffuse>1.0000 0.6824 0.0000 1</diffuse>
            </material>
        </visual>
    </gazebo>
    <gazebo reference="arm_top_collection-box-v1_2">
        <visual>
            <material>
                <ambient>0.9529 0.6275 0.0706 1</ambient>
                <diffuse>0.9529 0.6275 0.0706 1</diffuse>
            </material>
        </visual>
    </gazebo>
    <gazebo reference="arm_top_Component2_2">
        <visual>
            <material>
                <ambient>0.4784 0.4784 0.4784 1</ambient>
                <diffuse>0.4784 0.4784 0.4784 1</diffuse>
            </material>
        </visual>
    </gazebo>
    <gazebo>
        <plugin filename="libgz-sim-joint-position-controller-system.so" name="gz::sim::systems::JointPositionController">
            <joint_name>arm_joint3_copy</joint_name>
            <topic>joint3_copy_cmd</topic>
            <p_gain>800</p_gain>
            <i_gain>10.0</i_gain>
            <d_gain>80</d_gain>
            <i_max>100</i_max>
            <i_min>-100</i_min>
            <cmd_max>500</cmd_max>
            <cmd_min>-500</cmd_min>
            <cmd_offset>0.0</cmd_offset>
        </plugin>
    </gazebo>
    <gazebo>
        <plugin filename="libgz-sim-joint-position-controller-system.so" name="gz::sim::systems::JointPositionController">
            <joint_name>arm_joint4_copy</joint_name>
            <topic>joint4_copy_cmd</topic>
            <p_gain>500</p_gain>
            <i_gain>5.0</i_gain>
            <d_gain>50</d_gain>
            <i_max>80</i_max>
            <i_min>-80</i_min>
            <cmd_max>500</cmd_max>
            <cmd_min>-500</cmd_min>
            <cmd_offset>0.0</cmd_offset>
        </plugin>
    </gazebo>
    <gazebo>
        <plugin filename="libgz-sim-joint-position-controller-system.so" name="gz::sim::systems::JointPositionController">
            <joint_name>arm_joint5_copy</joint_name>
            <topic>joint5_copy_cmd</topic>
            <p_gain>500</p_gain>
            <i_gain>5.0</i_gain>
            <d_gain>50</d_gain>
            <i_max>80</i_max>
            <i_min>-80</i_min>
            <cmd_max>500</cmd_max>
            <cmd_min>-500</cmd_min>
            <cmd_offset>0.0</cmd_offset>
        </plugin>
    </gazebo>
    <gazebo>
        <plugin filename="libgz-sim-joint-state-publisher-system.so" name="gz::sim::systems::JointStatePublisher">
            <joint_name>arm_joint3_copy</joint_name>
            <joint_name>arm_joint4_copy</joint_name>
            <joint_name>arm_joint5_copy</joint_name>
        </plugin>
    </gazebo>
    <gazebo reference="arm_link3_copy">
        <material>Gazebo/Green</material>
    </gazebo>
    <gazebo reference="arm_link4_copy">
        <material>Gazebo/Purple</material>
    </gazebo>
    <gazebo reference="arm_link5_copy">
        <material>Gazebo/White</material>
    </gazebo>
<link name="arm_link2_copy1">
        <inertial>
            <origin xyz="0.0023258 0.39197 0.0012124" rpy="0 0 0"/>
            <mass value="7.2824"/>
            <inertia ixx="0.56505" ixy="-0.0011051" ixz="0.00023875" iyy="0.0071252" iyz="-0.00046822" izz="0.56327"/>
        </inertial>
        <visual>
            <origin xyz="0 0 -0.445" rpy="0 0 0"/>
            <geometry><mesh filename="package://vehicle_arm_sim/meshes/link2.STL" scale="1 1 1"/></geometry>
            <material name="arm_link2_material_1">
                <color rgba="0.0000 0.0196 0.6000 1.0"/>
            </material>
        </visual>
        <collision>
            <origin xyz="0 0 0" rpy="0 0 0"/>
            <geometry><mesh filename="package://vehicle_arm_sim/meshes/link2.STL" scale="1 1 1"/></geometry>
        </collision>
    </link><link name="arm_link4_copy1">
        <inertial>
            <origin xyz="-0.044144 0.0378 -0.072925" rpy="0 0 0"/>
            <mass value="0.86357"/>
            <inertia ixx="0.0063398" ixy="0.00091722" ixz="-0.0017328" iyy="0.0061419" iyz="0.0015638" izz="0.0031822"/>
        </inertial>
        <visual>
            <origin xyz="0.008 -0.334 -0.459" rpy="0 0 0"/>
            <geometry>
                <mesh filename="package://vehicle_arm_sim/meshes/link4.STL"/>
            </geometry>
            <material name="arm_link4_material_2">
                <color rgba="0.292156862745098 0.119607843137255 0.933333333333333 1"/>
            </material>
        </visual>
        <collision>
            <origin xyz="0 0 0" rpy="0 0 0"/>
            <geometry>
                <mesh filename="package://vehicle_arm_sim/meshes/link4.STL"/>
            </geometry>
        </collision>
    </link><link name="arm_link3_copy1">
        <inertial>
            <origin xyz="-0.033163 -0.04027 -0.0050659" rpy="0 0 0"/>
            <mass value="1.4316"/>
            <inertia ixx="0.0037572" ixy="-0.00082268" ixz="-0.0011479" iyy="0.043868" iyz="-0.00017008" izz="0.044751"/>
        </inertial>
        <visual>
            <origin xyz="0.069 -0.378 -0.330" rpy="0 0 0"/>
            <geometry>
                <mesh filename="package://vehicle_arm_sim/meshes/link3.STL"/>
            </geometry>
            <material name="arm_link3_material_3">
                <color rgba="0.592156862745098 0.79607843137255 0.233333333333333 1"/>
            </material>
        </visual>
        <collision>
            <origin xyz="0 0 0" rpy="0 0 0"/>
            <geometry>
                <mesh filename="package://vehicle_arm_sim/meshes/link3.STL"/>
            </geometry>
        </collision>
    </link><link name="arm_yanthra_link_copy1">
        <inertial>
            <origin xyz="0 0 0" rpy="0 0 0"/>
            <mass value="0.01"/>
            <inertia ixx="0.0001" ixy="0" ixz="0" iyy="0.0001" iyz="0" izz="0.0001"/>
        </inertial>
        <visual>
            <geometry>
                <box size="0.001 0.001 0.001"/>
            </geometry>
        </visual>
        <collision>
            <origin xyz="0 0 0" rpy="0 0 0"/>
            <geometry>
                <box size="0.001 0.001 0.001"/>
            </geometry>
        </collision>
    </link><link name="arm_link5_origin_copy1">
        <inertial>
            <origin xyz="0 0 0" rpy="0 0 0"/>
            <mass value="0.01"/>
            <inertia ixx="0.0001" ixy="0" ixz="0" iyy="0.0001" iyz="0" izz="0.0001"/>
        </inertial>
        <visual>
            <geometry>
                <box size="0.001 0.001 0.001"/>
            </geometry>
        </visual>
        <collision>
            <origin xyz="0 0 0" rpy="0 0 0"/>
            <geometry>
                <box size="0.001 0.001 0.001"/>
            </geometry>
        </collision>
    </link><link name="arm_link5_copy1">
        <inertial>
            <origin xyz="-0.24702 0.0038414 0.0022102" rpy="0 0 0"/>
            <mass value="0.50477"/>
            <inertia ixx="0.00073373" ixy="0.00051748" ixz="-0.00013446" iyy="0.014642" iyz="4.7355E-06" izz="0.014712"/>
        </inertial>
        <visual>
            <origin xyz="-0.209 -0.300 -0.329" rpy="0 0 0"/>
            <geometry>
                <mesh filename="package://vehicle_arm_sim/meshes/link5.STL"/>
            </geometry>
            <material name="arm_link5_material_4">
                <color rgba="0.25 0.28 0.3 1"/>
            </material>
        </visual>
        <collision>
            <origin xyz="0 0 0" rpy="0 0 0"/>
            <geometry>
                <mesh filename="package://vehicle_arm_sim/meshes/link5.STL"/>
            </geometry>
        </collision>
    </link><link name="arm_ee_link_copy1">
        <inertial>
            <origin xyz="0 0 0" rpy="0 0 0"/>
            <mass value="0.01"/>
            <inertia ixx="0.0001" ixy="0" ixz="0" iyy="0.0001" iyz="0" izz="0.0001"/>
        </inertial>
        <visual>
            <geometry>
                <box size="0.001 0.001 0.001"/>
            </geometry>
        </visual>
        <collision>
            <origin xyz="0 0 0" rpy="0 0 0"/>
            <geometry>
                <box size="0.001 0.001 0.001"/>
            </geometry>
        </collision>
    </link><joint name="base-v1_to_arm_link2_joint_copy1" type="fixed">
        <parent link="base-v1"/>
        <child link="arm_link2_copy1"/>
        <origin xyz="0.355298 0.394908 0.913409" rpy="-1.521774 -1.550976 -0.049013"/>
    </joint><joint name="arm_joint4_copy1" type="prismatic">
        <origin xyz="0 0.33411 0" rpy="0 0 0"/>
        <parent link="arm_link2_copy1"/>
        <child link="arm_link4_copy1"/>
        <axis xyz="0 1 0"/>
        <limit lower="-0.250" upper="0.350" effort="100" velocity="0.5"/>
    </joint><joint name="arm_joint3_copy1" type="revolute">
        <origin xyz="-0.069574 0.009556 -0.12761" rpy="0 0.006395 0"/>
        <parent link="arm_link4_copy1"/>
        <child link="arm_link3_copy1"/>
        <axis xyz="0 -1 0"/>
        <limit lower="-0.9" upper="0.0" effort="100" velocity="1.0"/>
    </joint><joint name="arm_yantra_joint_copy1" type="fixed">
        <origin xyz="0 -0.082 0" rpy="0 0 0"/>
        <parent link="arm_link3_copy1"/>
        <child link="arm_yanthra_link_copy1"/>
    </joint><joint name="arm_link5_origin_joint_copy1" type="fixed">
        <origin xyz="0 0 0" rpy="0 0 0"/>
        <parent link="arm_yanthra_link_copy1"/>
        <child link="arm_link5_origin_copy1"/>
    </joint><joint name="arm_joint5_copy1" type="prismatic">
        <origin xyz="0.278326 0.012934 -0.000824" rpy="0 0 0"/>
        <parent link="arm_link5_origin_copy1"/>
        <child link="arm_link5_copy1"/>
        <axis xyz="1 0 0"/>
        <limit lower="0" upper="0.450" effort="100" velocity="0.5"/>
    </joint><joint name="arm_ee_joint_copy1" type="fixed">
        <origin xyz="0 0 0" rpy="0 0 0"/>
        <parent link="arm_link5_copy1"/>
        <child link="arm_ee_link_copy1"/>
    </joint><gazebo>
        <plugin filename="libgz-sim-joint-position-controller-system.so" name="gz::sim::systems::JointPositionController">
            <joint_name>arm_joint3_copy1</joint_name>
            <topic>arm_joint3_copy1_cmd</topic>
            <p_gain>800</p_gain>
            <i_gain>10.0</i_gain>
            <d_gain>80</d_gain>
            <i_max>100</i_max>
            <i_min>-100</i_min>
            <cmd_max>500</cmd_max>
            <cmd_min>-500</cmd_min>
            <cmd_offset>0.0</cmd_offset>
        </plugin>
    </gazebo><gazebo>
        <plugin filename="libgz-sim-joint-position-controller-system.so" name="gz::sim::systems::JointPositionController">
            <joint_name>arm_joint4_copy1</joint_name>
            <topic>arm_joint4_copy1_cmd</topic>
            <p_gain>500</p_gain>
            <i_gain>5.0</i_gain>
            <d_gain>50</d_gain>
            <i_max>80</i_max>
            <i_min>-80</i_min>
            <cmd_max>500</cmd_max>
            <cmd_min>-500</cmd_min>
            <cmd_offset>0.0</cmd_offset>
        </plugin>
    </gazebo><gazebo>
        <plugin filename="libgz-sim-joint-position-controller-system.so" name="gz::sim::systems::JointPositionController">
            <joint_name>arm_joint5_copy1</joint_name>
            <topic>arm_joint5_copy1_cmd</topic>
            <p_gain>500</p_gain>
            <i_gain>5.0</i_gain>
            <d_gain>50</d_gain>
            <i_max>80</i_max>
            <i_min>-80</i_min>
            <cmd_max>500</cmd_max>
            <cmd_min>-500</cmd_min>
            <cmd_offset>0.0</cmd_offset>
        </plugin>
    </gazebo><gazebo>
        <plugin filename="libgz-sim-joint-state-publisher-system.so" name="gz::sim::systems::JointStatePublisher">
            <joint_name>arm_joint3_copy1</joint_name>
            <joint_name>arm_joint4_copy1</joint_name>
            <joint_name>arm_joint5_copy1</joint_name>
        </plugin>
    </gazebo><gazebo reference="arm_link2_copy1">
        <material>Gazebo/Blue</material>
    <visual><material><ambient>0.0000 0.0196 0.6000 1</ambient><diffuse>0.0000 0.0196 0.6000 1</diffuse></material></visual></gazebo><gazebo reference="arm_link3_copy1">
        <material>Gazebo/Green</material>
    </gazebo><gazebo reference="arm_link4_copy1">
        <material>Gazebo/Purple</material>
    </gazebo><gazebo reference="arm_link5_copy1">
        <material>Gazebo/White</material>
    </gazebo><link name="arm_top_colle.box-holding-v1_copy">
        <inertial>
            <origin xyz="0.21514017506062483 -0.015999999999999615 -0.013681869298376129" rpy="0.0 0.0 0.0"/>
            <mass value="0.342606"/>
            <inertia ixx="0.00043003932571770157" iyy="0.011122906290419732" izz="0.01075133830821507" ixy="5.613330715348987e-17" iyz="-1.0905687748614085e-16" ixz="-0.001077144265120561"/>
        </inertial>
        <visual name="colle.box-holding-v1_visual">
            <origin xyz="0 0 0" rpy="0 0 0"/>
            <geometry>
                <mesh filename="package://vehicle_arm_sim/meshes/colle.box-holding-v1.stl" scale="0.001 0.001 0.001"/>
            </geometry>
            <material name="arm_top_colle.box-holding-v1_material">
                <color rgba="0.8431 0.5608 0.0784 1.0"/>
            </material>
        </visual>
        <collision name="colle.box-holding-v1_collision">
            <origin xyz="0.0 0.0 0.0" rpy="0.0 0.0 0.0"/>
            <geometry>
                <mesh filename="package://vehicle_arm_sim/meshes/colle.box-holding-v1.stl" scale="0.001 0.001 0.001"/>
            </geometry>
        </collision>
    </link><link name="arm_top_Component2_copy">
        <inertial>
            <origin xyz="-0.24465088161211476 0.010585973180471987 0.11091969064068309" rpy="0.0 -0.0 -4.494409300504508e-94"/>
            <mass value="2.732553"/>
            <inertia ixx="0.019945673059615317" iyy="0.3093216702465301" izz="0.2907100794669303" ixy="-0.0006508067571328429" iyz="-0.002854246151097408" ixz="-0.0036114894797260747"/>
        </inertial>
        <visual name="Component2_visual">
            <origin xyz="0.400815 -0.003195 0.178301" rpy="0 0 1.570796"/>
            <geometry>
                <mesh filename="package://vehicle_arm_sim/meshes/Component2.stl" scale="0.001 0.001 0.001"/>
            </geometry>
            <material name="arm_top_Component2_material">
                <color rgba="0.7020 0.7020 0.7020 1.0"/>
            </material>
        </visual>
        <collision name="Component2_collision">
            <origin xyz="0.400815 -0.0031948999999999988 0.17830079" rpy="1.8488927466117464e-31 -3.646298014371762e-62 1.5707963267948966"/>
            <geometry>
                <mesh filename="package://vehicle_arm_sim/meshes/Component2.stl" scale="0.001 0.001 0.001"/>
            </geometry>
        </collision>
    </link><link name="jointt_copy">
        <visual>
            <origin xyz="0 0 0" rpy="0 0 0"/>
            <geometry>
                <sphere radius="0.025"/>
            </geometry>
            <material name="jointt_material">
                <color rgba="0.3569 0.6078 0.8353 1.0"/>
            </material>
        </visual>
        <collision>
            <geometry>
                <sphere radius="0.05"/>
            </geometry>
        </collision>
        <inertial>
            <mass value="1"/>
            <inertia ixx="0.001" ixy="0" ixz="0" iyy="0.001" iyz="0" izz="0.001"/>
        </inertial>
    </link><link name="arm_top_colle.box-holding-v1_2_copy">
        <inertial>
            <origin xyz="0.32628701238474833 -1.1652900866465644e-14 0.015681866892208914" rpy="0.0 -0.0 0.0"/>
            <mass value="0.342606"/>
            <inertia ixx="0.00043003932571770076" iyy="0.011122906290419676" izz="0.010751338308214758" ixy="-3.662363552223758e-17" iyz="9.057648485122138e-17" ixz="-0.0010771442651205756"/>
        </inertial>
        <visual name="colle.box-holding-v1_visual">
            <origin xyz="0.541427 0.016 0.002" rpy="3.141593 0 3.141593"/>
            <geometry><mesh filename="package://vehicle_arm_sim/meshes/colle.box-holding-v1.stl" scale="0.001 0.001 0.001"/></geometry>
            <material name="arm_top_colle.box-holding-v1_2_material">
                <color rgba="0.9020 0.5255 0.0980 1.0"/>
            </material>
        </visual>
        <collision name="colle.box-holding-v1_collision">
            <origin xyz="0.5414271874453744 0.01599999999998829 0.001999997593832927" rpy="3.14159265358979 1.3045120539345528e-15 3.141592653589793"/>
            <geometry><mesh filename="package://vehicle_arm_sim/meshes/colle.box-holding-v1.stl" scale="0.001 0.001 0.001"/></geometry>
        </collision>
    </link><link name="arm_top_collection-box-v1_copy">
        <inertial>
            <origin xyz="-0.046580819250886946 -0.3000000000000152 0.041453016072315683" rpy="-7.006492321624085e-46 -0.0 0.0"/>
            <mass value="2.808761"/>
            <inertia ixx="0.13035730185851852" iyy="0.025524525896721398" izz="0.11899707598580728" ixy="-4.5945544145968535e-16" iyz="1.1696557964289162e-17" ixz="-0.001106377875146882"/>
        </inertial>
        <visual name="collection-box-v1_visual">
            <origin xyz="-0.13617 0 0.150561" rpy="1.570796 -1.47461 0"/>
            <geometry>
                <mesh filename="package://vehicle_arm_sim/meshes/collection-box-v1.stl" scale="0.001 0.001 0.001"/>
            </geometry>
            <material name="arm_top_collection-box-v1_material">
                <color rgba="0.8078 0.5529 0.1098 1.0"/>
            </material>
        </visual>
        <collision name="collection-box-v1_collision">
            <origin xyz="-0.13616983694617538 -1.3358203432289884e-14 0.15056128893417614" rpy="1.570796326794917 -1.4746101983838649 -1.8764486226169754e-14"/>
            <geometry>
                <mesh filename="package://vehicle_arm_sim/meshes/collection-box-v1.stl" scale="0.001 0.001 0.001"/>
            </geometry>
        </collision>
    </link><link name="jointt2_copy">
        <visual>
            <origin xyz="0 0 0" rpy="0 0 0"/>
            <geometry>
                <sphere radius="0.025"/>
            </geometry>
            <material name="jointt2_material">
                <color rgba="0.3569 0.6078 0.8353 1.0"/>
            </material>
        </visual>
        <collision>
            <geometry>
                <sphere radius="0.05"/>
            </geometry>
        </collision>
        <inertial>
            <mass value="1"/>
            <inertia ixx="0.001" ixy="0" ixz="0" iyy="0.001" iyz="0" izz="0.001"/>
        </inertial>
    </link><joint name="base-v1_to_arm_top_colle.box-holding-v1_joint_copy" type="fixed">
        <parent link="base-v1"/>
        <child link="arm_top_colle.box-holding-v1_copy"/>
        <origin xyz="0.881082 -0.201367 0.898889" rpy="0 0 1.581046"/>
    </joint><joint name="arm_top_colle.box-holding-v1_Rigid-1_copy" type="fixed">
        <origin xyz="0.54134 -0.012373 0.001869" rpy="-1.47461 0 -1.570796"/>
        <parent link="arm_top_colle.box-holding-v1_copy"/>
        <child link="arm_top_Component2_copy"/>
    </joint><joint name="arm_top_colle.box-holding-v1_to_jointt_joint_copy" type="fixed">
        <parent link="arm_top_colle.box-holding-v1_copy"/>
        <child link="jointt_copy"/>
        <origin xyz="0.715118 -0.419133 0.000544" rpy="0 0 0"/>
    </joint><joint name="arm_top_Component2_Rigid-2_copy" type="fixed">
        <origin xyz="-0.535715 -0.006695 -0.069385" rpy="3.141593 1.47461 -1.570796"/>
        <parent link="arm_top_Component2_copy"/>
        <child link="arm_top_colle.box-holding-v1_2_copy"/>
    </joint><joint name="arm_top_colle.box-holding-v1_Rigid-3_copy" type="fixed">
        <origin xyz="0.539427 0.016 0.072255" rpy="0 -0.096186 0"/>
        <parent link="arm_top_colle.box-holding-v1_2_copy"/>
        <child link="arm_top_collection-box-v1_copy"/>
    </joint><joint name="arm_top_colle.box-holding-v1_2_to_jointt2_joint_copy" type="fixed">
        <parent link="arm_top_colle.box-holding-v1_2_copy"/>
        <child link="jointt2_copy"/>
        <origin xyz="-0.238891 0.328853 0.004636" rpy="0 0 0"/>
    </joint><gazebo reference="arm_top_colle.box-holding-v1_copy">
        <visual>
            <material>
                <ambient>0.8431 0.5608 0.0784 1</ambient>
                <diffuse>0.8431 0.5608 0.0784 1</diffuse>
            </material>
        </visual>
    </gazebo><gazebo reference="arm_top_Component2_copy">
        <visual>
            <material>
                <ambient>0.7020 0.7020 0.7020 1</ambient>
                <diffuse>0.7020 0.7020 0.7020 1</diffuse>
            </material>
        </visual>
    </gazebo><gazebo reference="jointt_copy">
        <visual>
            <material>
                <ambient>0.3569 0.6078 0.8353 1</ambient>
                <diffuse>0.3569 0.6078 0.8353 1</diffuse>
            </material>
        </visual>
    </gazebo><gazebo reference="jointt2_copy">
        <visual>
            <material>
                <ambient>0.3569 0.6078 0.8353 1</ambient>
                <diffuse>0.3569 0.6078 0.8353 1</diffuse>
            </material>
        </visual>
    </gazebo><gazebo reference="arm_top_colle.box-holding-v1_2_copy">
        <visual>
            <material>
                <ambient>0.9020 0.5255 0.0980 1</ambient>
                <diffuse>0.9020 0.5255 0.0980 1</diffuse>
            </material>
        </visual>
    </gazebo><gazebo reference="arm_top_collection-box-v1_copy">
        <visual>
            <material>
                <ambient>0.8078 0.5529 0.1098 1</ambient>
                <diffuse>0.8078 0.5529 0.1098 1</diffuse>
            </material>
        </visual>
    </gazebo></robot>